Workbook

Sheet Hoja1
B2: INTRAPERSONALES | F2: =SUM(B5+B8+B11+B14+B17) -> 104
B4: Conocimiento Emocional de si mismo
B5: =SUM('Plantilla de Correción'!C9+'Plantilla de Correción'!C11+'Plantilla de Correción'!C25+'Plantilla de Correción'!C37+'Plantilla de Correción'!C54+'Plantilla de Correción'!F10+'Plantilla de Correción'!F35+'Plantilla de Correción'!I8) -> 31
B7: Asertividad
B8: =SUM('Plantilla de Correción'!C24+'Plantilla de Correción'!C39+'Plantilla de Correción'!F14+'Plantilla de Correción'!F29+'Plantilla de Correción'!F43+'Plantilla de Correción'!I3+'Plantilla de Correción'!I18) -> 24
B10: Autoconcepto
B11: =SUM('Plantilla de Correción'!C13+'Plantilla de Correción'!C26+'Plantilla de Correción'!C42+'Plantilla de Correción'!F3+'Plantilla de Correción'!F17+'Plantilla de Correción'!F32+'Plantilla de Correción'!F47+'Plantilla de Correción'!I6+'Plantilla de Correción'!I21) -> 9
B13: Autorrealizacion
B14: =SUM('Plantilla de Correción'!C8+'Plantilla de Correción'!C23+'Plantilla de Correción'!C38+'Plantilla de Correción'!C53+'Plantilla de Correción'!F13+'Plantilla de Correción'!F42+'Plantilla de Correción'!F57+'Plantilla de Correción'!F28+'Plantilla de Correción'!I17) -> 26
B16: Independencia
B17: =SUM('Plantilla de Correción'!C5+'Plantilla de Correción'!C21+'Plantilla de Correción'!C34+'Plantilla de Correción'!C50+'Plantilla de Correción'!F39+'Plantilla de Correción'!F54+'Plantilla de Correción'!I13) -> 14
B19: INTERPERSONALES | F19: =SUM(B22+B25+B28) -> 74 | G19: =SUM((F19)-('Plantilla de Correción'!J57+Resultados!J11+Resultados!J22+Resultados!J48+'Plantilla de Correción'!J121)) -> 74
B21: Relaciones Interpersonales
B22: =SUM('Plantilla de Correción'!C12+'Plantilla de Correción'!C25+'Plantilla de Correción'!C33+'Plantilla de Correción'!C41+'Plantilla de Correción'!C57+'Plantilla de Correción'!F9+'Plantilla de Correción'!F16+'Plantilla de Correción'!F31+'Plantilla de Correción'!F46+'Plantilla de Correción'!I5+'Plantilla de Correción'!I20) -> 35
B24: Responsabilidad Social
B25: =SUM('Plantilla de Correción'!C18+'Plantilla de Correción'!C32+'Plantilla de Correción'!C48+'Plantilla de Correción'!F8+'Plantilla de Correción'!F19+'Plantilla de Correción'!F23+'Plantilla de Correción'!F37+'Plantilla de Correción'!F45+'Plantilla de Correción'!F51+'Plantilla de Correción'!I11) -> 22
B27: Empatia
B28: =SUM('Plantilla de Correción'!C20+'Plantilla de Correción'!C46+'Plantilla de Correción'!C57+'Plantilla de Correción'!F8+'Plantilla de Correción'!F19+'Plantilla de Correción'!F45+'Plantilla de Correción'!I11+'Plantilla de Correción'!I16) -> 17
B30: ADAPTABILIDAD | F30: =SUM(B36+B39+B33) -> 58
B32: Solucion de Problemas
B33: =SUM('Plantilla de Correción'!C3+'Plantilla de Correción'!C17+'Plantilla de Correción'!C31+'Plantilla de Correción'!C47+'Plantilla de Correción'!F7+'Plantilla de Correción'!F22+'Plantilla de Correción'!F36+'Plantilla de Correción'!I10) -> 16
B35: Prueba de la realidad
B36: =SUM('Plantilla de Correción'!C10+'Plantilla de Correción'!C37+'Plantilla de Correción'!C40+'Plantilla de Correción'!C55+'Plantilla de Correción'!F15+'Plantilla de Correción'!F30+'Plantilla de Correción'!F35+'Plantilla de Correción'!F44+'Plantilla de Correción'!I4+'Plantilla de Correción'!I19) -> 26
B38: Flexibilidad
B39: =SUM('Plantilla de Correción'!C16+'Plantilla de Correción'!C30+'Plantilla de Correción'!C45+'Plantilla de Correción'!F6+'Plantilla de Correción'!F21+'Plantilla de Correción'!F34+'Plantilla de Correción'!F50+'Plantilla de Correción'!I23) -> 16
B41: MANEJO DEL ESTRÉS | F41: =SUM(B44+B47) -> 29
B43: Tolerancia al Estrés
B44: =SUM('Plantilla de Correción'!C6+'Plantilla de Correción'!C22+'Plantilla de Correción'!C35+'Plantilla de Correción'!C51+'Plantilla de Correción'!F11+'Plantilla de Correción'!F25+'Plantilla de Correción'!F40+'Plantilla de Correción'!F55+'Plantilla de Correción'!I14) -> 16
B46: Control de Impulsos
B47: =SUM('Plantilla de Correción'!C15+'Plantilla de Correción'!C29+'Plantilla de Correción'!C44+'Plantilla de Correción'!F5+'Plantilla de Correción'!F20+'Plantilla de Correción'!F33+'Plantilla de Correción'!F49+'Plantilla de Correción'!I9+'Plantilla de Correción'!I22) -> 13
B49: ANIMO GENERAL | F49: =SUM(B52+B55) -> 42
B51: Felicidad | G51: VALIDEZ
B52: =SUM('Plantilla de Correción'!C4+'Plantilla de Correción'!C19+'Plantilla de Correción'!C33+'Plantilla de Correción'!C49+'Plantilla de Correción'!F9+'Plantilla de Correción'!F24+'Plantilla de Correción'!F38+'Plantilla de Correción'!F52+'Plantilla de Correción'!I12) -> 24
G53: Impresión positiva
B54: Optimismo | G54: =SUM('Plantilla de Correción'!C7+'Plantilla de Correción'!C36+'Plantilla de Correción'!C52+'Plantilla de Correción'!F12+'Plantilla de Correción'!F26+'Plantilla de Correción'!F41+'Plantilla de Correción'!F56+'Plantilla de Correción'!I15) -> 15
B55: =SUM('Plantilla de Correción'!C13+'Plantilla de Correción'!C22+'Plantilla de Correción'!C28+'Plantilla de Correción'!C56+'Plantilla de Correción'!F27+'Plantilla de Correción'!F53+'Plantilla de Correción'!F55+'Plantilla de Correción'!I24) -> 18
G56: Impresión Negativa
G57: =SUM('Plantilla de Correción'!C14+'Plantilla de Correción'!C27+'Plantilla de Correción'!C43+'Plantilla de Correción'!F4+'Plantilla de Correción'!F18+'Plantilla de Correción'!F48+'Plantilla de Correción'!I7) -> 33

Sheet Hoja4
E6: GENERAL | J6: =Hoja3!K4 -> 41.695339
E7: INTRAPERSONAL | J7: =Hoja3!G2 -> 61.382511
E8: Comprensión de sí mismo (CM) | J8: =Hoja3!G5 -> 103.4375
E9: Asertividad (AS) | J9: =Hoja3!G8 -> 94.141631
E10: Autoconcepto (AC) | J10: =Hoja3!G11 -> 36.238095
E11: Autorrealizacion (AR) | J11: =Hoja3!G14 -> 65.325444
E12: Independencia (IN) | J12: =Hoja3!G17 -> 55.234375
E13: INTERPERSONALES | J13: =Hoja3!G19 -> 49.511521
E14: Empatia (EM) | J14: =Hoja3!G28 -> 40.894988
E15: Relaciones Interpersonales (RI) | J15: =Hoja3!G22 -> 77.001661
E16: Responsabilidad Social (RS) | J16: =Hoja3!G25 -> 35.283976
E17: ADAPTABILIDAD | J17: =Hoja3!G30 -> 49.05297
E18: Solucion de Problemas (SP) | J18: =Hoja3!G33 -> 48.51087
E19: Prueba de la Realidad (PR) | J19: =Hoja3!G36 -> 63.629032
E20: Flexibilidad (FL) | J20: =Hoja3!G39 -> 60.061728
E21: MANEJO DE LA TENSION | J21: =Hoja3!G41 -> 39.021739
E22: Manejo del Estrés (ME) | J22: =Hoja3!G44 -> 53.031915
E23: Control de Impulsos (CI) | J23: =Hoja3!G47 -> 42.477798
E24: ANIMO GENERAL | J24: =Hoja3!G49 -> 51.086957
E25: Felicidad (FE) | J25: =Hoja3!G52 -> 60.584795
E26: Optimismo (OP) | J26: =Hoja3!G55 -> 49.618834

Sheet Hoja5
B2: NORTH AMERICAN NORMATIVE DATA
B4: Descriptive Statistics in raw Scores for the North American Sanmple
B5: AJ | F5: AN | G5: AO
B6: EQI | F6: Mean | G6: Sd
B8: Positive Impression | F8: 20.35 | G8: 5.3
B9: Negative Impression | F9: 10.66 | G9: 4.26
B10: Inconsistency Index | F10: 5.32 | G10: 2.89
B12: TOTAL EQ | F12: 465.31 | G12: 49.99
B13: Intrapersonl EQ | F13: 156.7 | G13: 20.47
B14: Interpersonal EQ | F14: 99.52 | G14: 10.85
B15: Adaptability EQ | F15: 100.32 | G15: 12.46
B16: Stress Management EQ | F16: 68.27 | G16: 9.66
B17: General Mood EQ | F17: 70.5 | G17: 8.74
B19: Emotional self-Awareness | F19: 29.79 | G19: 5.28
B20: Assertiveness | F20: 25.82 | G20: 4.66
B21: Self-Regard | F21: 35.78 | G21: 6.3
... B33: Optimism | F33: 32.98 | G33: 4.46

Sheet Datos de Filiación
A1: @dropdown
A3: Martin Castellano 2001
C7: Nombre
C9: Apellidos
C11: Fecha de Nacimiento
C13: Edad | E13: 13 AÑOS
C15: Sexo | E15: MASCULINO
C17: Ocupacion | E17: ESTUDIANTE
C19: Fecha de Aplicación
B25: Para Corregir la prueba del BARÓN Ud. debe de introducr los datos de filiación en esta hoja y luego de introducidos estos Ud. debera de pasar a la Hoja de "Plantilla de Correción" para introducir en las columnas de color Plomo los numeros de las respuestas dadas por el sujeto. Luego de haber introducidos los datos Ud. debera de fiijarse el la Hoja de "valdez" para ver si realmente la prueba es consistente y luego de corroborado esto pasara Ud. a imprimir la hoja de "resultados" y la hoja del "Perfil gráfico" para al final con estos datos poder hacer un perfil del sujeto que Ud. esta examinando.

Sheet Plantilla de Correción
A1: items | B1: Pun. Directo | C1: Punt. Convertido | D1: items | E1: Pun. Directo | F1: Punt. Convertido | G1: items | H1: Pun. Directo | I1: Punt. Convertido
A2: 1
A3: 1 | B3: 3 | C3: =0+B3 -> 3 | D3: 56 | E3: 5 | F3: =6-E3 -> 1 | G3: =SUM($A$2+D57) -> 111 | H3: 4 | I3: =6-H3 -> 2
A4: =SUM($A$2+A3) -> 2 | B4: 5 | C4: =6-B4 -> 1 | D4: =SUM($A$2+D3) -> 57 | E4: 5 | F4: =0+E4 -> 5 | G4: =SUM($A$2+G3) -> 112 | H4: 5 | I4: =0+H4 -> 5
A5: =SUM($A$2+A4) -> 3 | B5: 3 | C5: =B5 -> 3 | D5: =SUM($A$2+D4) -> 58 | E5: 5 | F5: =6-E5 -> 1 | G5: =SUM($A$2+G4) -> 113 | H5: 1 | I5: =0+H5 -> 1
A6: =SUM($A$2+A5) -> 4 | B6: 1 | C6: =0+B6 -> 1 | D6: =SUM($A$2+D5) -> 59 | E6: 1 | F6: =6-E6 -> 5 | G6: =SUM($A$2+G5) -> 114 | H6: 1 | I6: =0+H6 -> 1
A7: =SUM($A$2+A6) -> 5 | B7: 2 | C7: =0+B7 -> 2 | D7: =SUM($A$2+D6) -> 60 | E7: 1 | F7: =0+E7 -> 1 | G7: =SUM($A$2+G6) -> 115 | H7: 4 | I7: =0+H7 -> 4
A8: =SUM($A$2+A7) -> 6 | B8: 4 | C8: =0+B8 -> 4 | D8: =SUM($A$2+D7) -> 61 | E8: 4 | F8: =0+E8 -> 4 | G8: =SUM($A$2+G7) -> 116 | H8: 4 | I8: =6-H8 -> 2
A9: =SUM($A$2+A8) -> 7 | B9: 5 | C9: =0+B9 -> 5 | D9: =SUM($A$2+D8) -> 62 | E9: 5 | F9: =0+E9 -> 5 | G9: =SUM($A$2+G8) -> 117 | H9: 5 | I9: =6-H9 -> 1
A10: =SUM($A$2+A9) -> 8 | B10: 5 | C10: =0+B10 -> 5 | D10: =SUM($A$2+D9) -> 63 | E10: 5 | F10: =0+E10 -> 5 | G10: =SUM($A$2+G9) -> 118 | H10: 5 | I10: =6-H10 -> 1
A11: =SUM($A$2+A10) -> 9 | B11: 5 | C11: =0+B11 -> 5 | D11: =SUM($A$2+D10) -> 64 | E11: 5 | F11: =6-E11 -> 1 | G11: =SUM($A$2+G10) -> 119 | H11: 1 | I11: =0+H11 -> 1
A12: =SUM($A$2+A11) -> 10 | B12: 3 | C12: =6-B12 -> 3 | D12: =SUM($A$2+D11) -> 65 | E12: 1 | F12: =0+E12 -> 1 | G12: =SUM($A$2+G11) -> 120 | H12: 4 | I12: =0+H12 -> 4
A13: =SUM($A$2+A12) -> 11 | B13: 1 | C13: =0+B13 -> 1 | D13: =SUM($A$2+D12) -> 66 | E13: 4 | F13: =6-E13 -> 2 | G13: =SUM($A$2+G12) -> 121 | H13: 5 | I13: =6-H13 -> 1
A14: =SUM($A$2+A13) -> 12 | B14: 5 | C14: =0+B14 -> 5 | D14: =SUM($A$2+D13) -> 67 | E14: 5 | F14: =0+E14 -> 5 | G14: =SUM($A$2+G13) -> 122 | H14: 4 | I14: =6-H14 -> 2
A15: =SUM($A$2+A14) -> 13 | B15: 5 | C15: =6-B15 -> 1 | D15: =SUM($A$2+D14) -> 68 | E15: 5 | F15: =6-E15 -> 1 | G15: =SUM($A$2+G14) -> 123 | H15: 1 | I15: =0+H15 -> 1
A16: =SUM($A$2+A15) -> 14 | B16: 5 | C16: =6-B16 -> 1 | D16: =SUM($A$2+D15) -> 69 | E16: 3 | F16: =6-E16 -> 3 | G16: =SUM($A$2+G15) -> 124 | H16: 4 | I16: =0+H16 -> 4
A17: =SUM($A$2+A16) -> 15 | B17: 2 | C17: =0+B17 -> 2 | D17: =SUM($A$2+D16) -> 70 | E17: 5 | F17: =6-E17 -> 1 | G17: =SUM($A$2+G16) -> 125 | H17: 4 | I17: =6-H17 -> 2
A18: =SUM($A$2+A17) -> 16 | B18: 2 | C18: =0+B18 -> 2 | D18: =SUM($A$2+D17) -> 71 | E18: 5 | F18: =0+E18 -> 5 | G18: =SUM($A$2+G17) -> 126 | H18: 5 | I18: =6-H18 -> 1
A19: =SUM($A$2+A18) -> 17 | B19: 3 | C19: =6-B19 -> 3 | D19: =SUM($A$2+D18) -> 72 | E19: 2 | F19: =0+E19 -> 2 | G19: =SUM($A$2+G18) -> 127 | H19: 2 | I19: =6-H19 -> 4
A20: =SUM($A$2+A19) -> 18 | B20: 5 | C20: =6-B20 -> 1 | D20: =SUM($A$2+D19) -> 73 | E20: 5 | F20: =6-E20 -> 1 | G20: =SUM($A$2+G19) -> 128 | H20: 2 | I20: =6-H20 -> 4
A21: =SUM($A$2+A20) -> 19 | B21: 5 | C21: =6-B21 -> 1 | D21: =SUM($A$2+D20) -> 74 | E21: 2 | F21: =0+E21 -> 2 | G21: =SUM($A$2+G20) -> 129 | H21: 1 | I21: =0+H21 -> 1
A22: =SUM($A$2+A21) -> 20 | B22: 5 | C22: =0+B22 -> 5 | D22: =SUM($A$2+D21) -> 75 | E22: 1 | F22: =6-E22 -> 5 | G22: =SUM($A$2+G21) -> 130 | H22: 4 | I22: =6-H22 -> 2
A23: =SUM($A$2+A22) -> 21 | B23: 3 | C23: =6-B23 -> 3 | D23: =SUM($A$2+D22) -> 76 | E23: 2 | F23: =6-E23 -> 4 | G23: =SUM($A$2+G22) -> 131 | H23: 2 | I23: =6-H23 -> 4
A24: =SUM($A$2+A23) -> 22 | B24: 1 | C24: =6-B24 -> 5 | D24: =SUM($A$2+D23) -> 77 | E24: 5 | F24: =6-E24 -> 1 | G24: =SUM($A$2+G23) -> 132 | H24: 4 | I24: =6-H24 -> 2
A25: =SUM($A$2+A24) -> 23 | B25: 2 | C25: =6-B25 -> 4 | D25: =SUM($A$2+D24) -> 78 | E25: 1 | F25: =0+E25 -> 1 | G25: =SUM($A$2+G24) -> 133 | H25: 4 | I25: =0+H25 -> 4
A26: =SUM($A$2+A25) -> 24 | B26: 5 | C26: =6-B26 -> 1 | D26: =SUM($A$2+D25) -> 79 | E26: 5 | F26: =0+E26 -> 5 | I26: =SUM(I3:I25)+(C58)+(F58) -> 323
A27: =SUM($A$2+A26) -> 25 | B27: 5 | C27: =0+B27 -> 5 | D27: =SUM($A$2+D26) -> 80 | E27: 1 | F27: =0+E27 -> 1
A28: =SUM($A$2+A27) -> 26 | B28: 2 | C28: =0+B28 -> 2 | D28: =SUM($A$2+D27) -> 81 | E28: 4 | F28: =0+E28 -> 4
A29: =SUM($A$2+A28) -> 27 | B29: 2 | C29: =6-B29 -> 4 | D29: =SUM($A$2+D28) -> 82 | E29: 5 | F29: =6-E29 -> 1
A30: =SUM($A$2+A29) -> 28 | B30: 5 | C30: =6-B30 -> 1 | D30: =SUM($A$2+D29) -> 83 | E30: 5 | F30: =6-E30 -> 1
A31: =SUM($A$2+A30) -> 29 | B31: 4 | C31: =6-B31 -> 2 | D31: =SUM($A$2+D30) -> 84 | E31: 2 | F31: =0+E31 -> 2
A32: =SUM($A$2+A31) -> 30 | B32: 3 | C32: =6-B32 -> 3 | D32: =SUM($A$2+D31) -> 85 | E32: 1 | F32: =0+E32 -> 1
A33: =SUM($A$2+A32) -> 31 | B33: 3 | C33: =0+B33 -> 3 | D33: =SUM($A$2+D32) -> 86 | E33: 5 | F33: =6-E33 -> 1
A34: =SUM($A$2+A33) -> 32 | B34: 2 | C34: =6-B34 -> 4 | D34: =SUM($A$2+D33) -> 87 | E34: 5 | F34: =6-E34 -> 1
A35: =SUM($A$2+A34) -> 33 | B35: 1 | C35: =0+B35 -> 1 | D35: =SUM($A$2+D34) -> 88 | E35: 5 | F35: =0+E35 -> 5
A36: =SUM($A$2+A35) -> 34 | B36: 1 | C36: =0+B36 -> 1 | D36: =SUM($A$2+D35) -> 89 | E36: 1 | F36: =0+E36 -> 1
A37: =SUM($A$2+A36) -> 35 | B37: 5 | C37: =6-B37 -> 1 | D37: =SUM($A$2+D36) -> 90 | E37: 2 | F37: =0+E37 -> 2
A38: =SUM($A$2+A37) -> 36 | B38: 5 | C38: =6-B38 -> 1 | D38: =SUM($A$2+D37) -> 91 | E38: 5 | F38: =6-E38 -> 1
A39: =SUM($A$2+A38) -> 37 | B39: 5 | C39: =0+B39 -> 5 | D39: =SUM($A$2+D38) -> 92 | E39: 4 | F39: =6-E39 -> 2
A40: =SUM($A$2+A39) -> 38 | B40: 5 | C40: =6-B40 -> 1 | D40: =SUM($A$2+D39) -> 93 | E40: 4 | F40: =6-E40 -> 2
...

Sheet Validez
C2: VALIDEZ
C9: Máximo 3 ítems pueden ser omitidos
A10: AC | B10: ='Plantilla de Correción'!B13 -> 1 | C10: ='Plantilla de Correción'!B26 -> 5 | D10: ='Plantilla de Correción'!B42 -> 1 | E10: ='Plantilla de Correción'!E3 -> 5 | F10: ='Plantilla de Correción'!E17 -> 5 | G10: ='Plantilla de Correción'!E32 -> 1 | H10: ='Plantilla de Correción'!E47 -> 1 | I10: ='Plantilla de Correción'!H6 -> 1 | J10: ='Plantilla de Correción'!H21 -> 1
A11: AR | B11: ='Plantilla de Correción'!B8 -> 4 | C11: ='Plantilla de Correción'!B23 -> 3 | D11: ='Plantilla de Correción'!B38 -> 5 | E11: ='Plantilla de Correción'!B53 -> 5 | F11: ='Plantilla de Correción'!E13 -> 4 | G11: ='Plantilla de Correción'!E30 -> 5 | H11: ='Plantilla de Correción'!E42 -> 4 | I11: ='Plantilla de Correción'!E57 -> 5 | J11: ='Plantilla de Correción'!E17 -> 5
A12: RI | B12: ='Plantilla de Correción'!B12 -> 3 | C12: ='Plantilla de Correción'!B25 -> 2 | D12: ='Plantilla de Correción'!B33 -> 3 | E12: ='Plantilla de Correción'!B41 -> 4 | F12: ='Plantilla de Correción'!B57 -> 2 | G12: ='Plantilla de Correción'!E9 -> 5 | H12: ='Plantilla de Correción'!E16 -> 3 | I12: ='Plantilla de Correción'!E31 -> 2 | J12: ='Plantilla de Correción'!E46 -> 4 | K12: ='Plantilla de Correción'!H5 -> 1 | L12: ='Plantilla de Correción'!H20 -> 2
A13: RS | B13: ='Plantilla de Correción'!B18 -> 2 | C13: ='Plantilla de Correción'!B32 -> 3 | D13: ='Plantilla de Correción'!B48 -> 5 | E13: ='Plantilla de Correción'!E8 -> 4 | F13: ='Plantilla de Correción'!E19 -> 2 | G13: ='Plantilla de Correción'!E23 -> 2 | H13: ='Plantilla de Correción'!E37 -> 2 | I13: ='Plantilla de Correción'!E45 -> 2 | J13: ='Plantilla de Correción'!E51 -> 1 | K13: ='Plantilla de Correción'!H11 -> 1
A14: PR | B14: ='Plantilla de Correción'!B10 -> 5 | C14: ='Plantilla de Correción'!B37 -> 5 | D14: ='Plantilla de Correción'!B40 -> 5 | E14: ='Plantilla de Correción'!B55 -> 5 | F14: ='Plantilla de Correción'!E15 -> 5 | G14: ='Plantilla de Correción'!E30 -> 5 | H14: ='Plantilla de Correción'!E35 -> 5 | I14: ='Plantilla de Correción'!E44 -> 4 | J14: ='Plantilla de Correción'!H4 -> 5 | K14: ='Plantilla de Correción'!H19 -> 2
A15: TE | B15: ='Plantilla de Correción'!B6 -> 1 | C15: ='Plantilla de Correción'!B22 -> 5 | D15: ='Plantilla de Correción'!B35 -> 1 | E15: ='Plantilla de Correción'!B51 -> 4 | F15: ='Plantilla de Correción'!E11 -> 5 | G15: ='Plantilla de Correción'!E25 -> 1 | H15: ='Plantilla de Correción'!E40 -> 4 | I15: ='Plantilla de Correción'!E55 -> 1 | J15: ='Plantilla de Correción'!H14 -> 4
A16: CI | B16: ='Plantilla de Correción'!B15 -> 5 | C16: ='Plantilla de Correción'!B29 -> 2 | D16: ='Plantilla de Correción'!B44 -> 5 | E16: ='Plantilla de Correción'!E5 -> 5 | F16: ='Plantilla de Correción'!E20 -> 5 | G16: ='Plantilla de Correción'!E33 -> 5 | H16: ='Plantilla de Correción'!E49 -> 5 | I16: ='Plantilla de Correción'!H9 -> 5 | J16: ='Plantilla de Correción'!H22 -> 4
A17: FE | B17: ='Plantilla de Correción'!B4 -> 5 | C17: ='Plantilla de Correción'!B19 -> 3 | D17: ='Plantilla de Correción'!B33 -> 3 | E17: ='Plantilla de Correción'!B49 -> 1 | F17: ='Plantilla de Correción'!E9 -> 5 | G17: ='Plantilla de Correción'!E24 -> 5 | H17: ='Plantilla de Correción'!E38 -> 5 | I17: ='Plantilla de Correción'!E52 -> 5 | J17: ='Plantilla de Correción'!H12 -> 4
C20: Máximo 2 ítems pueden ser omitidos
A21: CM | B21: ='Plantilla de Correción'!B9 -> 5 | C21: ='Plantilla de Correción'!B11 -> 5 | D21: ='Plantilla de Correción'!B25 -> 2 | E21: ='Plantilla de Correción'!B37 -> 5 | F21: ='Plantilla de Correción'!B54 -> 2 | G21: ='Plantilla de Correción'!E10 -> 5 | H21: ='Plantilla de Correción'!E35 -> 5 | I21: ='Plantilla de Correción'!H8 -> 4
A22: EM | B22: ='Plantilla de Correción'!B20 -> 5 | C22: ='Plantilla de Correción'!B46 -> 1 | D22: ='Plantilla de Correción'!B57 -> 2 | E22: ='Plantilla de Correción'!E8 -> 4 | F22: ='Plantilla de Correción'!E19 -> 2 | G22: ='Plantilla de Correción'!E45 -> 2 | H22: ='Plantilla de Correción'!H11 -> 1 | I22: ='Plantilla de Correción'!H16 -> 4
A23: FL | B23: ='Plantilla de Correción'!B16 -> 5 | C23: ='Plantilla de Correción'!B30 -> 5 | D23: ='Plantilla de Correción'!B45 -> 5 | E23: ='Plantilla de Correción'!E6 -> 1 | F23: ='Plantilla de Correción'!E21 -> 2 | G23: ='Plantilla de Correción'!E34 -> 5 | H23: ='Plantilla de Correción'!E50 -> 5 | I23: ='Plantilla de Correción'!H25 -> 4
A24: SP | B24: ='Plantilla de Correción'!B3 -> 3 | C24: ='Plantilla de Correción'!B17 -> 2 | D24: ='Plantilla de Correción'!B31 -> 4 | E24: ='Plantilla de Correción'!B47 -> 1 | F24: ='Plantilla de Correción'!E7 -> 1 | G24: ='Plantilla de Correción'!E22 -> 1 | H24: ='Plantilla de Correción'!E36 -> 1 | I24: ='Plantilla de Correción'!H10 -> 5
A25: OP | B25: ='Plantilla de Correción'!B13 -> 1 | C25: ='Plantilla de Correción'!B22 -> 5 | D25: ='Plantilla de Correción'!B28 -> 2 | E25: ='Plantilla de Correción'!B56 -> 5 | F25: ='Plantilla de Correción'!E27 -> 1 | G25: ='Plantilla de Correción'!E53 -> 1 | H25: ='Plantilla de Correción'!E55 -> 1 | I25: ='Plantilla de Correción'!H24 -> 4
C27: Máximo 1 ítem pueden ser omitidos
A28: AS | B28: ='Plantilla de Correción'!B24 -> 1 | C28: ='Plantilla de Correción'!B39 -> 5 | D28: ='Plantilla de Correción'!E14 -> 5 | E28: ='Plantilla de Correción'!E29 -> 5 | F28: ='Plantilla de Correción'!E43 -> 5 | G28: ='Plantilla de Correción'!H3 -> 4 | H28: ='Plantilla de Correción'!H18 -> 5
A29: IN | B29: ='Plantilla de Correción'!B5 -> 3 | C29: ='Plantilla de Correción'!B21 -> 5 | D29: ='Plantilla de Correción'!B34 -> 2 | E29: ='Plantilla de Correción'!B50 -> 5 | F29: ='Plantilla de Correción'!E9 -> 5 | G29: ='Plantilla de Correción'!E54 -> 4 | H29: ='Plantilla de Correción'!H13 -> 5
D34: INDICE DE INCONSISTENCIA
D35: Más de 12 respuestas se invalida
B36: ='Plantilla de Correción'!C25 -> 4 | C36: ='Plantilla de Correción'!C34 -> 4 | D36: ='Plantilla de Correción'!C43 -> 5 | E36: ='Plantilla de Correción'!C49 -> 1 | F36: ='Plantilla de Correción'!F3 -> 1 | G36: ='Plantilla de Correción'!F7 -> 1 | H36: ='Plantilla de Correción'!F32 -> 1 | I36: ='Plantilla de Correción'!F34 -> 1 | J36: ='Plantilla de Correción'!F47 -> 1 | K36: ='Plantilla de Correción'!I9 -> 1
B37: ='Plantilla de Correción'!C54 -> 4 | C37: ='Plantilla de Correción'!C50 -> 1 | D37: ='Plantilla de Correción'!F48 -> 4 | E37: ='Plantilla de Correción'!F38 -> 1 | F37: ='Plantilla de Correción'!F17 -> 1 | G37: ='Plantilla de Correción'!F36 -> 1 | H37: ='Plantilla de Correción'!I21 -> 1 | I37: ='Plantilla de Correción'!F50 -> 1 | J37: ='Plantilla de Correción'!I6 -> 1 | K37: ='Plantilla de Correción'!I22 -> 2
B38: =SUM(B36-B37) -> 0 | C38: =SUM(C36-C37) -> 3 | D38: =SUM(D36-D37) -> 1 | E38: =SUM(E36-E37) -> 0 | F38: =SUM(F36-F37) -> 0 | G38: =SUM(G36-G37) -> 0 | H38: =SUM(H36-H37) -> 0 | I38: =SUM(I36-I37) -> 0 | ... K38: =SUM(K36-K37) -> -1

Sheet Resultados
A1: HOJA DE RESULTADOS DEL INVETARIO EMOCIONAL DE BARON
A4: Nombre y Apellidos | C4: =+'Datos de Filiación'!E7 | F4: =+'Datos de Filiación'!E9
A5: Fecha de Nacimento | C5: =+'Datos de Filiación'!E11 | F5: Edad | G5: =+'Datos de Filiación'!E13 -> 13 AÑOS
A6: Genero | C6: =+'Datos de Filiación'!E15 -> MASCULINO | F6: Ocupación | G6: =+'Datos de Filiación'!E17 -> ESTUDIANTE
A7: Fecha de Aplicación | C7: 37545 | F7: F. Correción | G7: =NOW() -> 45092.82
C11: GENERAL | F11: =Hoja4!J6 -> 41.695339
C12: Optimismo (OP) | F12: =Hoja4!J26 -> 49.618834
C13: Felicidad (FE) | F13: =Hoja4!J25 -> 60.584795
C14: ESTADO DE ANIMO G | F14: =Hoja4!J24 -> 51.086957
C15: Control de Impulsos (CI) | F15: =Hoja4!J23 -> 42.477798
C16: Tolerancia al Estrés (TE) | F16: =Hoja4!J22 -> 53.031915
C17: MANEJO DEL ESTRES | F17: =Hoja4!J21 -> 39.021739
C18: Flexibilidad (FL) | F18: =Hoja4!J20 -> 60.061728
C19: Prueba de la Realidad (PR) | F19: =Hoja4!J19 -> 63.629032
C20: Solucion de Problemas (SP) | F20: =Hoja4!J18 -> 48.51087
C21: ADAPTABILIDAD | F21: =Hoja4!J17 -> 49.05297
C22: Responsabilidad Social (RS) | F22: =Hoja4!J16 -> 35.283976
C23: Relaciones Interpersonales (RI) | F23: =Hoja4!J15 -> 77.001661
C24: Empatia (EM) | F24: =Hoja4!J14 -> 40.894988
C25: INTERPERSONAL | F25: =Hoja4!J13 -> 49.511521
C26: Independencia (IN) | F26: =Hoja4!J12 -> 55.234375
C27: Autorrealizacion (AR) | F27: =Hoja4!J11 -> 65.325444
C28: Autoconcepto (AC) | F28: =Hoja4!J10 -> 36.238095
C29: Asertividad (AS) | F29: =Hoja4!J9 -> 94.141631
C30: Comprensión de sí mismo (CM) | F30: =Hoja4!J8 -> 103.4375
C31: INTRAPERSONAL | F31: =Hoja4!J7 -> 61.382511

Sheet Hoja3
G1: CE
A2: INTRAPERSONAL | F2: =SUM(A5+A8+A11+A14+A17) -> 104 | G2: =(((F2-Hoja5!F13)/Hoja5!G13)*15)+100 -> 61.382511
I3: GENERAL | K3: CE
A4: Conocimiento Emocional de si mismo | I4: =SUM(F2+F19+E30+E41+E49)-('Plantilla de Correción'!C13+'Plantilla de Correción'!C22+'Plantilla de Correción'!C25+'Plantilla de Correción'!C33+'Plantilla de Correción'!C37+'Plantilla de Correción'!F9+'Plantilla de Correción'!F35+'Plantilla de Correción'!F55) -> 271 | K4: =(((I4-Hoja5!F12)/Hoja5!G12)*15)+100 -> 41.695339
A5: =Hoja1!B5 -> 31 | G5: =(((A5-Hoja5!F19)/Hoja5!G19)*15)+100 -> 103.4375
A7: Asertividad
A8: =Hoja1!B8 -> 24 | G8: =(((A8-Hoja5!F20)/Hoja5!G20)*15)+100 -> 94.141631
A10: Autoconcepto
A11: =Hoja1!B11 -> 9 | G11: =(((A11-Hoja5!F21)/Hoja5!G21)*15)+100 -> 36.238095
A13: Autorrealizacion
A14: =Hoja1!B14 -> 26 | G14: =(((A14-Hoja5!F22)/Hoja5!G22)*15)+100 -> 65.325444
A16: Independencia
A17: =Hoja1!B17 -> 14 | G17: =(((A17-Hoja5!F23)/Hoja5!G23)*15)+100 -> 55.234375
A19: INTERPERSONALES | E19: =SUM(A22+A25+A28) -> 74 | F19: =SUM((E19)-('Plantilla de Correción'!C57+'Plantilla de Correción'!F8+'Plantilla de Correción'!F19+'Plantilla de Correción'!F45+'Plantilla de Correción'!I11)) -> 63 | G19: =(((F19-Hoja5!F14)/Hoja5!G14)*15)+100 -> 49.511521
A21: Relaciones Interpersonales
A22: =Hoja1!B22 -> 35 | G22: =(((A22-Hoja5!F25)/Hoja5!G25)*15)+100 -> 77.001661
A24: Responsabilidad Social
A25: =Hoja1!B25 -> 22 | G25: =(((A25-Hoja5!F26)/Hoja5!G26)*15)+100 -> 35.283976
A27: Empatia
A28: =Hoja1!B28 -> 17 | G28: =(((A28-Hoja5!F24)/Hoja5!G24)*15)+100 -> 40.894988
A30: ADAPTABILIDAD | E30: =SUM(A36+A39+A33) -> 58 | G30: =(((E30-Hoja5!F15)/Hoja5!G15)*15)+100 -> 49.05297
A32: Solucion de Problemas
A33: =Hoja1!B33 -> 16 | G33: =(((A33-Hoja5!F27)/Hoja5!G27)*15)+100 -> 48.51087
A35: Prueba de la realidad
A36: =Hoja1!B36 -> 26 | G36: =(((A36-Hoja5!F28)/Hoja5!G28)*15)+100 -> 63.629032
A38: Flexibilidad
A39: =Hoja1!B39 -> 16 | G39: =(((A39-Hoja5!F29)/Hoja5!G29)*15)+100 -> 60.061728
A41: MANEJO DEL ESTRÉS | E41: =SUM(A44+A47) -> 29 | G41: =(((E41-Hoja5!F16)/Hoja5!G16)*15)+100 -> 39.021739
A43: Tolerancia al Estrés
A44: =Hoja1!B44 -> 16 | G44: =(((A44-Hoja5!F30)/Hoja5!G30)*15)+100 -> 53.031915
A46: Control de Impulsos
A47: =Hoja1!B47 -> 13 | G47: =(((A47-Hoja5!F31)/Hoja5!G31)*15)+100 -> 42.477798
A49: ANIMO GENERAL | E49: =SUM(A52+A55) -> 42 | G49: =(((E49-Hoja5!F17)/Hoja5!G17)*15)+100 -> 51.086957
H50: VALIDEZ
A51: Felicidad | H51: Impresión Positiva | K51: CE
A52: =Hoja1!B52 -> 24 | G52: =(((A52-Hoja5!F32)/Hoja5!G32)*15)+100 -> 60.584795 | H52: =Hoja1!G54 -> 15 | K52: =((('Plantilla de Correción'!BE62-Hoja5!F8)/Hoja5!G8)*15)+100 -> 42.40566
A54: Optimismo | H54: Impresión Negativa
A55: =Hoja1!B55 -> 18 | G55: =(((A55-Hoja5!F33)/Hoja5!G33)*15)+100 -> 49.618834 | H55: =Hoja1!G57 -> 33 | K55: =((('Plantilla de Correción'!BE65-Hoja5!F9)/Hoja5!G9)*15)+100 -> 62.464789

Sheet Plantilla N.
A1: items | B1: Pun. Directo | C1: Punt. Convertido | D1: items | E1: Pun. Directo | F1: Punt. Convertido | G1: items | H1: Pun. Directo | I1: Punt. Convertido | AM1: CE
A2: 1 | L2: INTRAPERSONALES | P2: =SUM(L5+L8+L11+L14+L17) -> 128 | V2: VALIDEZ | AG2: INTRAPERSONAL | AL2: =SUM(AG5+AG8+AG11+AG14+AG17) -> 128 | AM2: =(((AL2-BH13)/BI13)*15)+100 -> 78.969223 | BD2: NORTH AMERICAN NORMATIVE DATA
A3: 1 | B3: 5 | C3: =0+B3 -> 5 | D3: 56 | E3: 3 | F3: =6-E3 -> 3 | G3: =SUM($A$2+D57) -> 111 | H3: 3 | I3: =6-H3 -> 3 | AO3: GENERAL | AQ3: CE
A4: =SUM($A$2+A3) -> 2 | B4: 3 | C4: =6-B4 -> 3 | D4: =SUM($A$2+D3) -> 57 | E4: 1 | F4: =0+E4 -> 1 | G4: =SUM($A$2+G3) -> 112 | H4: 5 | I4: =0+H4 -> 5 | L4: Conocimiento Emocional de si mismo | AG4: Conocimiento Emocional de si mismo | AO4: =SUM(AL2+AL19+AK30+AK41+AK49)-(C13+C22+C25+C33+C37+F9+F35+F55) -> 402 | AQ4: =(((AO4-BH12)/BI12)*15)+100 -> 81.003201 | BD4: Descriptive Statistics in raw Scores for the North American Sanmple
A5: =SUM($A$2+A4) -> 3 | B5: 4 | C5: =B5 -> 4 | D5: =SUM($A$2+D4) -> 58 | E5: 6 | F5: =6-E5 -> 0 | G5: =SUM($A$2+G4) -> 113 | H5: 5 | I5: =0+H5 -> 5 | L5: =SUM(C9+C11+C25+C37+C54+F10+F35+I8) -> 27 | AG5: =L5 -> 27 | AM5: =(((AG5-BH19)/BI19)*15)+100 -> 92.073864 | BD5: AJ | BH5: AN | BI5: AO
A6: =SUM($A$2+A5) -> 4 | B6: 0 | C6: =0+B6 -> 0 | D6: =SUM($A$2+D5) -> 59 | E6: 4 | F6: =6-E6 -> 2 | G6: =SUM($A$2+G5) -> 114 | H6: 3 | I6: =0+H6 -> 3 | AV6: GENERAL | BA6: =AQ4 -> 81.003201 | BD6: EQI | BH6: Mean | BI6: Sd
A7: =SUM($A$2+A6) -> 5 | B7: 4 | C7: =0+B7 -> 4 | D7: =SUM($A$2+D6) -> 60 | E7: 3 | F7: =0+E7 -> 3 | G7: =SUM($A$2+G6) -> 115 | H7: 1 | I7: =0+H7 -> 1 | L7: Asertividad | AG7: Asertividad | AV7: INTRAPERSONAL | BA7: =AM2 -> 78.969223
A8: =SUM($A$2+A7) -> 6 | B8: 4 | C8: =0+B8 -> 4 | D8: =SUM($A$2+D7) -> 61 | E8: 4 | F8: =0+E8 -> 4 | G8: =SUM($A$2+G7) -> 116 | H8: 2 | I8: =6-H8 -> 4 | L8: =SUM(C24+C39+F14+F29+F43+I3+I18) -> 19 | AG8: =L8 -> 19 | AM8: =(((AG8-BH20)/BI20)*15)+100 -> 78.04721 | AV8: Comprensión de sí mismo (CM) | BA8: =AM5 -> 92.073864 | BD8: Positive Impression | BH8: 20.35 | BI8: 5.3
A9: =SUM($A$2+A8) -> 7 | B9: 4 | C9: =0+B9 -> 4 | D9: =SUM($A$2+D8) -> 62 | E9: 3 | F9: =0+E9 -> 3 | G9: =SUM($A$2+G8) -> 117 | H9: 2 | I9: =6-H9 -> 4 | V9: Máximo 3 ítems pueden ser omitidos | AV9: Asertividad (AS) | BA9: =AM8 -> 78.04721 | BD9: Negative Impression | BH9: 10.66 | BI9: 4.26
A10: =SUM($A$2+A9) -> 8 | B10: 5 | C10: =0+B10 -> 5 | D10: =SUM($A$2+D9) -> 63 | E10: 5 | F10: =0+E10 -> 5 | G10: =SUM($A$2+G9) -> 118 | H10: 3 | I10: =6-H10 -> 3 | L10: Autoconcepto | T10: AC | U10: =B13 -> 1 | V10: =B26 -> 1 | W10: =B42 -> 4 | X10: =E3 -> 3 | Y10: =E17 -> 5 | Z10: =E32 -> 1 | AA10: =E47 -> 1 | AB10: =H6 -> 3 | AC10: =H21 -> 3 | AG10: Autoconcepto | AV10: Autoconcepto (AC) | BA10: =AM11 -> 67.190476 | BD10: Inconsistency Index | BH10: 5.32 | BI10: 2.89
A11: =SUM($A$2+A10) -> 9 | B11: 4 | C11: =0+B11 -> 4 | D11: =SUM($A$2+D10) -> 64 | E11: 2 | F11: =6-E11 -> 4 | G11: =SUM($A$2+G10) -> 119 | H11: 4 | I11: =0+H11 -> 4 | L11: =SUM(C13+C26+C42+F3+F17+F32+F47+I6+I21) -> 22 | T11: AR | U11: =B8 -> 4 | V11: =B23 -> 2 | W11: =B38 -> 3 | X11: =B53 -> 3 | Y11: =E13 -> 2 | Z11: =E30 -> 2 | AA11: =E42 -> 3 | AB11: =E57 -> 5 | AC11: =E17 -> 5 | AG11: =L11 -> 22 | AM11: =(((AG11-BH21)/BI21)*15)+100 -> 67.190476 | AV11: Autorrealizacion (AR) | BA11: =AM14 -> 86.035503
A12: =SUM($A$2+A11) -> 10 | B12: 3 | C12: =6-B12 -> 3 | D12: =SUM($A$2+D11) -> 65 | E12: 3 | F12: =0+E12 -> 3 | G12: =SUM($A$2+G11) -> 120 | H12: 5 | I12: =0+H12 -> 5 | T12: RI | U12: =B12 -> 3 | V12: =B25 -> 4 | W12: =B33 -> 2 | X12: =B41 -> 4 | Y12: =B57 -> 3 | Z12: =E9 -> 3 | AA12: =E16 -> 2 | AB12: =E31 -> 3 | AC12: =E46 -> 4 | AD12: =H5 -> 5 | AE12: =H20 -> 3 | AV12: Independencia (IN) | BA12: =AM17 -> 98.761161 | BD12: TOTAL EQ | BH12: 465.31 | BI12: 49.99
A13: =SUM($A$2+A12) -> 11 | B13: 1 | C13: =0+B13 -> 1 | D13: =SUM($A$2+D12) -> 66 | E13: 2 | F13: =6-E13 -> 4 | G13: =SUM($A$2+G12) -> 121 | H13: 5 | I13: =6-H13 -> 1 | L13: Autorrealizacion | T13: RS | U13: =B18 -> 4 | V13: =B32 -> 3 | W13: =B48 -> 2 | X13: =E8 -> 4 | Y13: =E19 -> 4 | Z13: =E23 -> 3 | AA13: =E37 -> 4 | AB13: =E45 -> 4 | AC13: =E51 -> 4 | AD13: =H11 -> 4 | AG13: Autorrealizacion | AV13: INTERPERSONALES | BA13: =AM19 -> 78.543779 | BD13: Intrapersonl EQ | BH13: 156.7 | BI13: 20.47
A14: =SUM($A$2+A13) -> 12 | B14: 1 | C14: =0+B14 -> 1 | D14: =SUM($A$2+D13) -> 67 | E14: 3 | F14: =0+E14 -> 3 | G14: =SUM($A$2+G13) -> 122 | H14: 2 | I14: =6-H14 -> 4 | L14: =SUM(C8+C23+C38+C53+F13+F42+F57+F28+I17) -> 33 | T14: PR | U14: =B10 -> 5 | V14: =B37 -> 3 | W14: =B40 -> 2 | X14: =B55 -> 3 | Y14: =E15 -> 3 | Z14: =E30 -> 2 | AA14: =E35 -> 4 | AB14: =E44 -> 2 | AC14: =H4 -> 5 | AD14: =H19 -> 2 | AG14: =L14 -> 33 | AM14: =(((AG14-BH22)/BI22)*15)+100 -> 86.035503 | AV14: Empatia (EM) | BA14: =AM28 -> 83.854415 | BD14: Interpersonal EQ | BH14: 99.52 | BI14: 10.85
A15: =SUM($A$2+A14) -> 13 | B15: 3 | C15: =6-B15 -> 3 | D15: =SUM($A$2+D14) -> 68 | E15: 3 | F15: =6-E15 -> 3 | G15: =SUM($A$2+G14) -> 123 | H15: 4 | I15: =0+H15 -> 4 | T15: TE | U15: =B6 -> 0 | V15: =B22 -> 4 | W15: =B35 -> 4 | X15: =B51 -> 2 | Y15: =E11 -> 2 | Z15: =E25 -> 4 | AA15: =E40 -> 2 | AB15: =E55 -> 4 | AC15: =H14 -> 2 | AV15: Relaciones Interpersonales (RI) | BA15: =AM22 -> 79.493355 | BD15: Adaptability EQ | BH15: 100.32 | BI15: 12.46
A16: =SUM($A$2+A15) -> 14 | B16: 2 | C16: =6-B16 -> 4 | D16: =SUM($A$2+D15) -> 69 | E16: 2 | F16: =6-E16 -> 4 | G16: =SUM($A$2+G15) -> 124 | H16: 1 | I16: =0+H16 -> 1 | L16: Independencia | T16: CI | U16: =B15 -> 3 | V16: =B29 -> 2 | W16: =B44 -> 2 | X16: =E5 -> 6 | Y16: =E20 -> 3 | Z16: =E33 -> 2 | AA16: =E49 -> 2 | AB16: =H9 -> 2 | AC16: =H22 -> 1 | AG16: Independencia | AV16: Responsabilidad Social (RS) | BA16: =AM25 -> 83.965517 | BD16: Stress Management EQ | BH16: 68.27 | BI16: 9.66
A17: =SUM($A$2+A16) -> 15 | B17: 4 | C17: =0+B17 -> 4 | D17: =SUM($A$2+D16) -> 70 | E17: 5 | F17: =6-E17 -> 1 | G17: =SUM($A$2+G16) -> 125 | H17: 3 | I17: =6-H17 -> 3 | L17: =SUM(C5+C21+C34+C50+F39+F54+I13) -> 27 | T17: FE | U17: =B4 -> 3 | V17: =B19 -> 3 | W17: =B33 -> 2 | X17: =B49 -> 4 | Y17: =E9 -> 3 | Z17: =E24 -> 4 | AA17: =E38 -> 2 | AB17: =E52 -> 4 | AC17: =H12 -> 5 | AG17: =L17 -> 27 | AM17: =(((AG17-BH23)/BI23)*15)+100 -> 98.761161 | AV17: ADAPTABILIDAD | BA17: =AM30 -> 88.780096 | BD17: General Mood EQ | BH17: 70.5 | BI17: 8.74
A18: =SUM($A$2+A17) -> 16 | B18: 4 | C18: =0+B18 -> 4 | D18: =SUM($A$2+D17) -> 71 | E18: 1 | F18: =0+E18 -> 1 | G18: =SUM($A$2+G17) -> 126 | H18: 4 | I18: =6-H18 -> 2 | AV18: Solucion de Problemas (SP) | BA18: =AM33 -> 84.380435
A19: =SUM($A$2+A18) -> 17 | B19: 3 | C19: =6-B19 -> 3 | D19: =SUM($A$2+D18) -> 72 | E19: 4 | F19: =0+E19 -> 4 | G19: =SUM($A$2+G18) -> 127 | H19: 2 | I19: =6-H19 -> 4 | L19: INTERPERSONALES | P19: =SUM(L22+L25+L28) -> 103 | Q19: =SUM((P19)-(J57+J63+J74+J100+J121)) -> 103 | AG19: INTERPERSONALES | AK19: =SUM(AG22+AG25+AG28) -> 103 | AL19: =SUM((AK19)-(C57+F8+F19+F45+I11)) -> 84 | AM19: =(((AL19-BH14)/BI14)*15)+100 -> 78.543779 | AV19: Prueba de la Realidad (PR) | BA19: =AM36 -> 98.575269 | BD19: Emotional self-Awareness | BH19: 29.79 | BI19: 5.28
A20: =SUM($A$2+A19) -> 18 | B20: 1 | C20: =6-B20 -> 5 | D20: =SUM($A$2+D19) -> 73 | E20: 3 | F20: =6-E20 -> 3 | G20: =SUM($A$2+G19) -> 128 | H20: 3 | I20: =6-H20 -> 3 | V20: Máximo 2 ítems pueden ser omitidos | AV20: Flexibilidad (FL) | BA20: =AM39 -> 87.839506 | BD20: Assertiveness | BH20: 25.82 | BI20: 4.66
A21: =SUM($A$2+A20) -> 19 | B21: 2 | C21: =6-B21 -> 4 | D21: =SUM($A$2+D20) -> 74 | E21: 3 | F21: =0+E21 -> 3 | G21: =SUM($A$2+G20) -> 129 | H21: 3 | I21: =0+H21 -> 3 | L21: Relaciones Interpersonales | T21: CM | U21: =B9 -> 4 | V21: =B11 -> 4 | W21: =B25 -> 4 | X21: =B37 -> 3 | Y21: =B54 -> 5 | Z21: =E10 -> 5 | AA21: =E35 -> 4 | AB21: =H8 -> 2 | AG21: Relaciones Interpersonales | AV21: MANEJO DE LA TENSION | BA21: =AM41 -> 91.81677 | BD21: Self-Regard | BH21: 35.78 | BI21: 6.3
A22: =SUM($A$2+A21) -> 20 | B22: 4 | C22: =0+B22 -> 4 | D22: =SUM($A$2+D21) -> 75 | E22: 3 | F22: =6-E22 -> 3 | G22: =SUM($A$2+G21) -> 130 | H22: 1 | I22: =6-H22 -> 5 | L22: =SUM(C12+C25+C33+C41+C57+F9+F16+F31+F46+I5+I20) -> 36 | T22: EM | U22: =B20 -> 1 | V22: =B46 -> 4 | W22: =B57 -> 3 | X22: =E8 -> 4 | Y22: =E19 -> 4 | Z22: =E45 -> 4 | AA22: =H11 -> 4 | AB22: =H16 -> 1 | AG22: =L22 -> 36 | AM22: =(((AG22-BH25)/BI25)*15)+100 -> 79.493355 | AV22: Manejo del Estrés (ME) | BA22: =AM44 -> 95.585106 | BD22: Self-Actualization | BH22: 37.72 | BI22: 5.07
A23: =SUM($A$2+A22) -> 21 | B23: 2 | C23: =6-B23 -> 4 | D23: =SUM($A$2+D22) -> 76 | E23: 3 | F23: =6-E23 -> 3 | G23: =SUM($A$2+G22) -> 131 | H23: 2 | I23: =6-H23 -> 4 | T23: FL | U23: =B16 -> 2 | V23: =B30 -> 3 | W23: =B45 -> 3 | X23: =E6 -> 4 | Y23: =E21 -> 3 | Z23: =E34 -> 3 | AA23: =E50 -> 3 | AB23: =H25 -> 5 | AV23: Control de Impulsos (CI) | BA23: =AM47 -> 90.435169 | BD23: Independence | BH23: 27.37 | BI23: 4.48
A24: =SUM($A$2+A23) -> 22 | B24: 5 | C24: =6-B24 -> 1 | D24: =SUM($A$2+D23) -> 77 | E24: 4 | F24: =6-E24 -> 2 | G24: =SUM($A$2+G23) -> 132 | H24: 1 | I24: =6-H24 -> 5 | L24: Responsabilidad Social | T24: SP | U24: =B3 -> 5 | V24: =B17 -> 4 | W24: =B31 -> 5 | X24: =B47 -> 5 | Y24: =E7 -> 3 | Z24: =E22 -> 3 | AA24: =E36 -> 3 | AB24: =H10 -> 3 | AG24: Responsabilidad Social | AV24: ANIMO GENERAL | BA24: =AM49 -> 80.263158 | BD24: Empathy | BH24: 33.51 | BI24: 4.19
A25: =SUM($A$2+A24) -> 23 | B25: 4 | C25: =6-B25 -> 2 | D25: =SUM($A$2+D24) -> 78 | E25: 4 | F25: =0+E25 -> 4 | G25: =SUM($A$2+G24) -> 133 | H25: 5 | I25: =0+H25 -> 5 | L25: =SUM(C18+C32+C48+F8+F19+F23+F37+F45+F51+I11) -> 38 | T25: OP | U25: =B13 -> 1 | V25: =B22 -> 4 | W25: =B28 -> 2 | X25: =B56 -> 4 | Y25: =E27 -> 5 | Z25: =E53 -> 4 | AA25: =E55 -> 4 | AB25: =H24 -> 1 | AG25: =L25 -> 38 | AM25: =(((AG25-BH26)/BI26)*15)+100 -> 83.965517 | AV25: Felicidad (FE) | BA25: =AM52 -> 78.128655 | BD25: Interpersonal Relationship | BH25: 44.23 | BI25: 6.02
A26: =SUM($A$2+A25) -> 24 | B26: 1 | C26: =6-B26 -> 5 | D26: =SUM($A$2+D25) -> 79 | E26: 1 | F26: =0+E26 -> 1 | I26: =SUM(I3:I25)+(C58)+(F58) -> 442 | AV26: Optimismo (OP) | BA26: =AM55 -> 86.61435 | BD26: Social Responsability | BH26: 43.27 | BI26: 4.93
A27: =SUM($A$2+A26) -> 25 | B27: 1 | C27: =0+B27 -> 1 | D27: =SUM($A$2+D26) -> 80 | E27: 5 | F27: =0+E27 -> 5 | L27: Empatia | V27: Máximo 1 ítem pueden ser omitidos | AG27: Empatia | BD27: Problem Solving | BH27: 31.79 | BI27: 4.6
A28: =SUM($A$2+A27) -> 26 | B28: 2 | C28: =0+B28 -> 2 | D28: =SUM($A$2+D27) -> 81 | E28: 4 | F28: =0+E28 -> 4 | L28: =SUM(C20+C46+C57+F8+F19+F45+I11+I16) -> 29 | T28: AS | U28: =B24 -> 5 | V28: =B39 -> 5 | W28: =E14 -> 3 | X28: =E29 -> 4 | Y28: =E43 -> 3 | Z28: =H3 -> 3 | AA28: =H18 -> 4 | AG28: =L28 -> 29 | AM28: =(((AG28-BH24)/BI24)*15)+100 -> 83.854415 | BD28: Reality Testing | BH28: 39.53 | BI28: 5.58
A29: =SUM($A$2+A28) -> 27 | B29: 2 | C29: =6-B29 -> 4 | D29: =SUM($A$2+D28) -> 82 | E29: 4 | F29: =6-E29 -> 2 | T29: IN | U29: =B5 -> 4 | V29: =B21 -> 2 | W29: =B34 -> 2 | X29: =B50 -> 1 | Y29: =E9 -> 3 | Z29: =E54 -> 1 | AA29: =H13 -> 5 | BD29: Flexibility | BH29: 28.94 | BI29: 4.86
A30: =SUM($A$2+A29) -> 28 | B30: 3 | C30: =6-B30 -> 3 | D30: =SUM($A$2+D29) -> 83 | E30: 2 | F30: =6-E30 -> 4 | L30: ADAPTABILIDAD | P30: =SUM(L36+L39+L33) -> 91 | AG30: ADAPTABILIDAD | AK30: =SUM(AG36+AG39+AG33) -> 91 | AM30: =(((AK30-BH15)/BI15)*15)+100 -> 88.780096 | BD30: Stress Tolerance | BH30: 33.66 | BI30: 5.64
A31: =SUM($A$2+A30) -> 29 | B31: 5 | C31: =6-B31 -> 1 | D31: =SUM($A$2+D30) -> 84 | E31: 3 | F31: =0+E31 -> 3 | BD31: Impulse Control | BH31: 34.59 | BI31: 5.63
A32: =SUM($A$2+A31) -> 30 | B32: 3 | C32: =6-B32 -> 3 | D32: =SUM($A$2+D31) -> 85 | E32: 1 | F32: =0+E32 -> 1 | L32: Solucion de Problemas | AG32: Solucion de Problemas | BD32: Happiness | BH32: 37.48 | BI32: 5.13
A33: =SUM($A$2+A32) -> 31 | B33: 2 | C33: =0+B33 -> 2 | D33: =SUM($A$2+D32) -> 86 | E33: 2 | F33: =6-E33 -> 4 | L33: =SUM(C3+C17+C31+C47+F7+F22+F36+I10) -> 27 | AG33: =L33 -> 27 | AM33: =(((AG33-BH27)/BI27)*15)+100 -> 84.380435 | BD33: Optimism | BH33: 32.98 | BI33: 4.46
A34: =SUM($A$2+A33) -> 32 | B34: 2 | C34: =6-B34 -> 4 | D34: =SUM($A$2+D33) -> 87 | E34: 3 | F34: =6-E34 -> 3 | W34: INDICE DE INCONSISTENCIA
A35: =SUM($A$2+A34) -> 33 | B35: 4 | C35: =0+B35 -> 4 | D35: =SUM($A$2+D34) -> 88 | E35: 4 | F35: =0+E35 -> 4 | L35: Prueba de la realidad | W35: Más de 12 respuestas se invalida | AG35: Prueba de la realidad
A36: =SUM($A$2+A35) -> 34 | B36: 3 | C36: =0+B36 -> 3 | D36: =SUM($A$2+D35) -> 89 | E36: 3 | F36: =0+E36 -> 3 | L36: =SUM(C10+C37+C40+C55+F15+F30+F35+F44+I4+I19) -> 39 | U36: =C25 -> 2 | V36: =C34 -> 4 | W36: =C43 -> 2 | X36: =C49 -> 4 | Y36: =F3 -> 3 | Z36: =F7 -> 3 | AA36: =F32 -> 1 | AB36: =F34 -> 3 | AC36: =F47 -> 1 | AD36: =I9 -> 4 | AG36: =L36 -> 39 | AM36: =(((AG36-BH28)/BI28)*15)+100 -> 98.575269
A37: =SUM($A$2+A36) -> 35 | B37: 3 | C37: =6-B37 -> 3 | D37: =SUM($A$2+D36) -> 90 | E37: 4 | F37: =0+E37 -> 4 | U37: =C54 -> 1 | V37: =C50 -> 5 | W37: =F48 -> 2 | X37: =F38 -> 4 | Y37: =F17 -> 1 | Z37: =F36 -> 3 | AA37: =I21 -> 3 | AB37: =F50 -> 3 | AC37: =I6 -> 3 | AD37: =I22 -> 5
A38: =SUM($A$2+A37) -> 36 | B38: 3 | C38: =6-B38 -> 3 | D38: =SUM($A$2+D37) -> 91 | E38: 2 | F38: =6-E38 -> 4 | L38: Flexibilidad | U38: =SUM(U36-U37) -> 1 | V38: =SUM(V36-V37) -> -1 | W38: =SUM(W36-W37) -> 0 | X38: =SUM(X36-X37) -> 0 | Y38: =SUM(Y36-Y37) -> 2 | Z38: =SUM(Z36-Z37) -> 0 | AA38: =SUM(AA36-AA37) -> -2 | AB38: =SUM(AB36-AB37) -> 0 | ... AD38: =SUM(AD36-AD37) -> -1 | AG38: Flexibilidad
A39: =SUM($A$2+A38) -> 37 | B39: 5 | C39: =0+B39 -> 5 | D39: =SUM($A$2+D38) -> 92 | E39: 2 | F39: =6-E39 -> 4 | L39: =SUM(C16+C30+C45+F6+F21+F34+F50+I23) -> 25 | AG39: =L39 -> 25 | AM39: =(((AG39-BH29)/BI29)*15)+100 -> 87.839506
A40: =SUM($A$2+A39) -> 38 | B40: 2 | C40: =6-B40 -> 4 | D40: =SUM($A$2+D39) -> 93 | E40: 2 | F40: =6-E40 -> 4
...
