Workbook

Sheet INTRO
B1: INVENTARIO DE PERSONALIDAD EYSENCK
B2: EPQ - B
B6: APELLIDOS Y NOMBRES: | D6: Nathalie Estigarribia
B7: EDAD | C7: 32 | F7: FECHA | G7: 45402
B8: OCUPACION | C8: Psicologo | F8: GRADO
G9: x
B10: EXAMINADO POR | C10: Jaquelin martinez prado | G10: x
G11: x
G12: x
G13: x
G14: x
G15: x
G16: x
G17: x
G18: x
G19: x
G20: PRIMARIA
G21: SECUNDARIA
G22: SUPERIOR

Sheet FORMAB
C1: AQUÍ TIENE ALGUNAS PREGUNTAS SOBRE EL MODO COMO USTED SE COMPORTA, SIENTE Y ACTUA
C2: DESPUES DE CADA PREGUNTA COLOQUE UN 1 DEBAJO DE "SI" O "NO", SEGÚN SEA SU RESPUESTA
C3: Trate de decidir lo más rápidamente. No hay contestaciones correctas ni incorrectas.
B4: Nº | G4: Si | H4: No | J4: Nº | O4: Si | P4: No
B5: 1 | C5: Le gusta la abundancia de excitación y bullicio a su alrededor? | H5: 1 | J5: 30 | K5: Alardea (se jacta) un poco a veces? | O5: 1 | T5: ESCALA
B6: =SUM(B5)+1 -> 2 | C6: Tiene a menudo un sentimiento de intranquilidad, como si quisiera | G6: 1 | J6: =SUM(J5)+1 -> 31 | K6: Es usted muy susceptible por algunas cosas? | P6: 1 | T6: L | V6: =G11+H18+H24+G30+P5+O11+P17+P23+P30 -> 2
C7: algo, pero sin saber qué? | J7: =SUM(J6)+1 -> 32 | K7: Le gusta más quedarse en casa que ir a una fiesta aburrida? | O7: 1
B8: =SUM(B6)+1 -> 3 | C8: Tiene casi siempre una contestación lista "a la mano" cuando se le habla? | G8: 1 | J8: =SUM(J7)+1 -> 33 | K8: Se pone a menudo inquieto que no puede permanecer sentado durante mucho rato en una silla? | P8: 1
B9: =SUM(B8)+1 -> 4 | C9: Se siente algunas veces feliz, otras triste sin una razón real? | G9: 1 | J9: =SUM(J8)+1 -> 34 | K9: Le gusta planear las cosas cuidadosamente con mucha anticipación? | O9: 1 | T9: DIMENSION
B10: =SUM(B9)+1 -> 5 | C10: Permanece usualmente retraído ( a) en fiestas y reuniones? | G10: 1 | J10: =SUM(J9)+1 -> 35 | K10: Tiene a menudo mareos (vértigos)? | O10: 1 | T10: N | V10: =G6+G9+G12+G15+G17+G20+G22+G25+G27+G29+G32+G34+O8+O10+O13+O15+O18+O20+O22+O25+O28+O31+O34 -> 12
B11: =SUM(B10)+1 -> 6 | C11: Cuando niño (a) hacía siempre inmediatamente lo que le decían sin renegar? | H11: 1 | J11: =SUM(J10)+1 -> 36 | K11: Contesta siempre una carta personal, tan pronto como puede, después de haberla leído?. | P11: 1 | T11: E | V11: =G5+G8+H10+G13+G16+G19+H21+G23+H26+G28+G31+G33+H35+P7+P9+P12+O14+P16+O19+O21+O24+P26+O29+O32 -> 10
B12: =SUM(B11)+1 -> 7 | C12: Se enfada a menudo? | G12: 1 | J12: =SUM(J11)+1 -> 37 | K12: Hace usted usualmente las cosas mejor resolviéndolas solo(a) que hablando a otros sobre ellas? | O12: 1
B13: =SUM(B12)+1 -> 8 | C13: Cuando lo (a) meten en una pelea, prefiere "sacar los trapos al aire" de una vez por | H13: 1 | J13: =SUM(J12)+1 -> 38 | K13: Le falta frecuentemente aire, sin haber hecho un trabajo pesado? | O13: 1
C14: todas, en vez de quedar callado (a) esperando que las cosas se calmen solas? | J14: =SUM(J13)+1 -> 39 | K14: Es usted generalmente una persona tolerante, que no se molesta si las cosas no estan percfectas? | O14: 1
B15: =SUM(B13)+1 -> 9 | C15: Es usted triste, melancólico (a)? | G15: 1 | J15: =SUM(J14)+1 -> 40 | K15: Sufre de los "nervios"? | P15: 1
B16: =SUM(B15)+1 -> 10 | C16: Le gusta mezclarse con la gente? | H16: 1 | J16: =SUM(J15)+1 -> 41 | K16: Le gustaría más planear que hacer cosas? | O16: 1
B17: =SUM(B16)+1 -> 11 | C17: Ha perdido a menudo el sueño por sus preocupaciones? | H17: 1 | J17: =SUM(J16)+1 -> 42 | K17: Deja algunas veces para mañana, lo que debería hacer hoy día? | O17: 1
B18: =SUM(B17)+1 -> 12 | C18: Se pone a veces malhumorado (a) | G18: 1 | J18: =SUM(J17)+1 -> 43 | K18: Se pone nervioso(a) en lugares tales como ascensores, trenes o túneles? | P18: 1
B19: =SUM(B18)+1 -> 13 | C19: Se catalogaría a sí mismo(a) como despreocupado(a) o confiado a su suerte? | H19: 1 | J19: =SUM(J18)+1 -> 44 | K19: Cuando hace nuevos amigos, ¿es usted quien inicia la relación o invita a que se produzca? | O19: 1
B20: =SUM(B19)+1 -> 14 | C20: Se decide a menudo demasiado tarde? | G20: 1 | J20: =SUM(J19)+1 -> 45 | K20: Sufre fuertes dolores de cabeza? | O20: 1
B21: =SUM(B20)+1 -> 15 | C21: Le gusta trabajar solo (a)? | G21: 1 | J21: =SUM(J20)+1 -> 46 | K21: Siente generalemente que las cosas se arreglarán por sí solas y que terminarán bien de algún modo? | P21: 1
B22: =SUM(B21)+1 -> 16 | C22: Se ha sentido a menudo apático (a) y cansado (a) sin razón? | G22: 1 | J22: =SUM(J21)+1 -> 47 | K22: Le cuesta trabajo coger el sueño al acostarse en las noches? | P22: 1
B23: =SUM(B22)+1 -> 17 | C23: Es por el contrario animado (a) y jovial? | H23: 1 | J23: =SUM(J22)+1 -> 48 | K23: Ha dicho alguna vez mentiras en su vida? | O23: 1
B24: =SUM(B23)+1 -> 18 | C24: Se ríe a menudo de chistes groseros? | H24: 1 | J24: =SUM(J23)+1 -> 49 | K24: Dice algunas veces lo primero que se le viene a la cabeza? | P24: 1
B25: =SUM(B24)+1 -> 19 | C25: Se siente a menudo hastiado (a)? | G25: 1 | J25: =SUM(J24)+1 -> 50 | K25: Se preocupa durante un tiempo demasiado largo, después de una experiencia embarazosa? | P25: 1
B26: =SUM(B25)+1 -> 20 | C26: Se siente incómodo (a) con vestidos que no son del diario? | G26: 1 | J26: =SUM(J25)+1 -> 51 | K26: Se mantiene usualmente hermético (a) o encerrado (a) en sí msmo (a), excepto con amigos muy | P26: 1
B27: =SUM(B26)+1 -> 21 | C27: Se distrae (fantasea) a menudo cuando trata de prestar atención a algo? | H27: 1 | K27: Intimos?
B28: =SUM(B27)+1 -> 22 | C28: Puede expresar en palabras fácilmente lo que piensa? | G28: 1 | J28: =SUM(J26)+1 -> 52 | K28: Se crea a menudo problemas por hacer cosas sin pensar? | P28: 1
B29: =SUM(B28)+1 -> 23 | C29: Se abstrae (se pierde en sus pensamientos) a menudo? | G29: 1 | J29: =SUM(J28)+1 -> 53 | K29: Le gusta contar chistes y referir historias graciosas a sus amigos? | O29: 1
B30: =SUM(B29)+1 -> 24 | C30: Está completamente tibre de prejuicios de cualquier tipo? | H30: 1 | J30: =SUM(J29)+1 -> 54 | K30: Se le hace más difícil ganar que perder un juego? | P30: 1
B31: =SUM(B30)+1 -> 25 | C31: Le gustan las bromas? | G31: 1 | J31: =SUM(J30)+1 -> 55 | K31: Se siente a menudo demasiado consciente de sí mismo(a) o poco natural cuando está con superiores? | P31: 1
B32: =SUM(B31)+1 -> 26 | C32: Piensa a menudo en su pasado? | H32: 1 | J32: =SUM(J31)+1 -> 56 | K32: Cuando todas las probabilidades están contra usted, ¿piensa aún usualmente que vale la pena | O32: 1
B33: =SUM(B32)+1 -> 27 | C33: Le gusta la buena comida? | G33: 1 | K33: probar suerte?
B34: =SUM(B33)+1 -> 28 | C34: Cuando se fastidia, necesita de algún(a) amigo(a) para hablar sobre ello? | G34: 1 | J34: =SUM(J32)+1 -> 57 | K34: Siente "sensaciones" raras en el abdómen, antes de algún hecho importante? | P34: 1
B35: =SUM(B34)+1 -> 29 | C35: Le molesta vender cosas o pedir dineroa la gente para alguna buena causa? | H35: 1

Sheet RESULTADOS
C1: APELLIDOS Y NOMBRES:
C2: =INTRO!D6 -> Nathalie Estigarribia
C3: EDAD | E3: =INTRO!C7 -> 32 | G3: FECHA | I3: =INTRO!G7 -> 45402
C4: OCUPACION | F4: =INTRO!C8 -> Psicologo
C5: GRADO | E5: =INTRO!G8
C6: EXAMINADO POR: | G6: =INTRO!C10 -> Jaquelin martinez prado | AQ6: L | AS6: N | AU6: E
H7: VALIDO | AQ7: 1 | AR7: VALIDO | AS7: 1 | AT7: ALTAMENTE ESTABLE | AU7: 1 | AV7: ALTAMENTE INTROVERTIDO | AX7: N | AY7: E
H8: INVALIDO | AQ8: 2 | AR8: VALIDO | AS8: 2 | AT8: ALTAMENTE ESTABLE | AU8: 2 | AV8: ALTAMENTE INTROVERTIDO | AX8: ALTAMENTE ESTABLE ALTAMENTE INTROVERTIDO | AY8: FLEMATICO | AZ8: FUERTE EQUILIBRADO-LENTO
C9: ESCALA | H9: Si L>4 = INVALIDO; Si L < 4 = VALIDO | AQ9: 3 | AR9: VALIDO | AS9: 3 | AT9: ALTAMENTE ESTABLE | AU9: 3 | AV9: ALTAMENTE INTROVERTIDO | AX9: TENDIENTE A ESTABLE ALTAMENTE INTROVERTIDO | AY9: FLEMATICO
C10: L | E10: =FORMAB!V6 -> 2 | H10: =LOOKUP(E10,AQ7:AR15) -> VALIDO | AQ10: 4 | AR10: VALIDO | AS10: 4 | AT10: ALTAMENTE ESTABLE | AU10: 4 | AV10: ALTAMENTE INTROVERTIDO | AX10: TENDIENTE A ESTABLE TENDIENTE A INTROVERSION | AY10: FLEMATICO
C11: DIMENSION | I11: INESTABLE | AQ11: 5 | AR11: INVALIDO | AS11: 5 | AT11: ALTAMENTE ESTABLE | AU11: 5 | AV11: ALTAMENTE INTROVERTIDO | AX11: ALTAMENTE INESTABLE ALTAMENTE EXTROVERTIDO | AY11: COLERICO
C12: N | E12: =FORMAB!V10 -> 12 | J12: N | AQ12: 6 | AR12: INVALIDO | AS12: 6 | AT12: ALTAMENTE ESTABLE | AU12: 6 | AV12: ALTAMENTE INTROVERTIDO | AX12: TENDIENTE A INESTABLE TENDIENTE A EXTROVERSION | AY12: COLERICO
C13: E | E13: =FORMAB!V11 -> 10 | K13: 24 | AQ13: 7 | AR13: INVALIDO | AS13: 7 | AT13: TENDIENTE A ESTABLE | AU13: 7 | AV13: ALTAMENTE INTROVERTIDO | AX13: TENDIENTE A INESTABLE ALTAMENTE EXTROVERTIDO | AY13: COLERICO
K14: 23 | AQ14: 8 | AR14: INVALIDO | AS14: 8 | AT14: TENDIENTE A ESTABLE | AU14: 8 | AV14: ALTAMENTE INTROVERTIDO | AX14: TENDIENTE A ESTABLE TENDIENTE A EXTROVERSION | AY14: SANGUINEO
D15: MELANCOLICO | K15: 22 | N15: COLERICO | AQ15: 9 | AR15: INVALIDO | AS15: 9 | AT15: TENDIENTE A ESTABLE | AU15: 9 | AV15: ALTAMENTE INTROVERTIDO | AX15: ALTAMENTE ESTABLE ALTAMENTE EXTROVERTIDO | AY15: SANGUINEO
K16: 21 | AS16: 10 | AT16: TENDIENTE A ESTABLE | AU16: 10 | AV16: ALTAMENTE INTROVERTIDO | AX16: TENDIENTE A ESTABLE ALTAMENTE EXTROVERTIDO | AY16: SANGUINEO
K17: 20
K18: 19
F19: Altamente | K19: 18 | N19: Altamente | AS19: 11 | AT19: TENDIENTE A ESTABLE | AU19: 11 | AV19: TENDIENTE A LA INTROVERSION | AX19: ALTAMENTE INESTABLE ALTAMENTE INTROVERTIDO | AY19: MELANCOLICO
K20: 17 | AS20: 12 | AT20: TENDIENTE A INESTABLE | AU20: 12 | AV20: TENDIENTE A LA INTROVERSION | AX20: TENDIENTE A INESTABLE ALTAMENTE INTROVERTIDO | AY20: MELANCOLICO
K21: 16 | AS21: 13 | AT21: TENDIENTE A INESTABLE | AU21: 13 | AV21: TENDIENTE A LA INTROVERSION | AX21: TENDIENTE A INESTABLE TENDIENTE A INTROVERSION | AY21: MELANCOLICO
K22: 15 | AS22: 14 | AT22: TENDIENTE A INESTABLE | AU22: 14 | AV22: TENDIENTE A LA EXTROVERSION
K23: 14 | AS23: 15 | AT23: TENDIENTE A INESTABLE | AU23: 15 | AV23: TENDIENTE A LA EXTROVERSION
K24: 13 | AS24: 16 | AT24: TENDIENTE A INESTABLE | AU24: 16 | AV24: TENDIENTE A LA EXTROVERSION
C25: E | D25: 0 1 2 3 4 5 6 7 8 9 10 11 12 13 | K25: 12 | L25: 15 16 17 18 19 20 21 22 23 24 | AS25: 17 | AT25: ALTAMENTE INESTABLE | AU25: 17 | AV25: ALTAMENTE EXTROVERTIDO
K26: 11 | AS26: 18 | AT26: ALTAMENTE INESTABLE | AU26: 18 | AV26: ALTAMENTE EXTROVERTIDO
K27: 10 | AS27: 19 | AT27: ALTAMENTE INESTABLE | AU27: 19 | AV27: ALTAMENTE EXTROVERTIDO
K28: 9 | AS28: 20 | AT28: ALTAMENTE INESTABLE | AU28: 20 | AV28: ALTAMENTE EXTROVERTIDO | AY28: FLEMATICO | AZ28: FUERTES EQUILIBRADOS LENTOS
K29: 8 | AS29: 21 | AT29: ALTAMENTE INESTABLE | AU29: 21 | AV29: ALTAMENTE EXTROVERTIDO | AY29: COLERICO | AZ29: FUERTES Y DESEQUILIBRADOS
K30: 7 | AS30: 22 | AT30: ALTAMENTE INESTABLE | AU30: 22 | AV30: ALTAMENTE EXTROVERTIDO | AY30: SANGUINEO | AZ30: FUERTES EQUILIBRADOS Y RAPIDOS
K31: 6 | AS31: 23 | AT31: ALTAMENTE INESTABLE | AU31: 23 | AV31: ALTAMENTE EXTROVERTIDO | AY31: MELANCOLICO | AZ31: DEBILES
F32: Altamente | K32: 5 | N32: Altamente | AS32: 24 | AT32: ALTAMENTE INESTABLE | AU32: 24 | AV32: ALTAMENTE EXTROVERTIDO
K33: 4
D34: FLEMATICO | K34: 3 | AS34: 1 | AT34: =LOOKUP(E12,AS7:AT32) -> TENDIENTE A INESTABLE | AW34: =LOOKUP(AT34:AT35,AX8:AY21) -> MELANCOLICO
K35: 2 | N35: SANGUINEO | AS35: 2 | AT35: =LOOKUP(E13,AU7:AV39) -> ALTAMENTE INTROVERTIDO
K36: 1 | AT36: =AT34&AT35 -> TENDIENTE A INESTABLE ALTAMENTE INTROVERTIDO
K37: 0 | AT37: =LOOKUP(AT36,AX8:AX21,AY8:AY21) -> MELANCOLICO
I38: ESTABLE | AT38: =LOOKUP(AT37,AY28:AY31,AZ28:AZ31) -> FUERTES Y DESEQUILIBRADOS
C42: DIAGNOSTICO
C44: Si N = | D44: =E12 -> 12 | E44: y E = | F44: =E13 -> 10 | G44: =C2 -> Nathalie Estigarribia | M44: es una persona con una tipología
...
