Workbook

Sheet CUESTIONARIO
B2: CUESTIONARIO DE HABILIDADES SOCIALES
B3: Isaias HURTADO SANTA CRUZ | C3: NOMBRE
B4: Isaias HURTADO SANTA CRUZ | C4: EXAMINADOR
B6: A = No me identifico , en la mayoría de las veces no me ocurre o no lo haría.
B7: B = No tiene que ver conmigo, aunque alguna vez me ocurra
B8: C = Me describe aproximadamente, aunque no siempre actúe así o me sienta así
B9: D = Muy de acuerdo, me sentiría así o actuaría así en la mayoría de los casos
B11: PREGUNTAS | C11: a | D11: b | E11: c | F11: d
B12: 1. A veces evito hacer preguntas por miedo a ser estúpido | C12: 1
B13: 2. Me cuesta telefonear a tiendas , oficinas, etc. para preguntar algo
B14: 3. Si al llegar a mi casa encuentro un defecto en algo que he comprado, voy a la tienda a devolverlo.
B15: 4. Cuando en una tienda atienden antes a alguien que entro después que yo, me quedo callado.
B16: 5. Si un vendedor insiste en enseñarme un producto que no deseo en absoluto , paso un mal rato para decirle que “NO”
B17: 6. A veces me resulta difícil pedir que me devuelvan algo que deje prestado.
B18: 7. Si en un restauran no me traen la comida como le había pedido, llamo al camarero y pido que me hagan de nuevo.
B19: 8. A veces no se que decir a personas atractivas al sexo opuesto.
B20: 9. Muchas veces cuando tengo que hacer un halago no se que decir.
B21: 10. Tiendo a guardar mis opiniones a mi mismo
B22: 11. A veces evito ciertas reuniones sociales por miedo a hacer o decir alguna tontería.
B23: 12. Si estoy en el cine y alguien me molesta con su conversación, me da mucho apuro pedirle que se calle.
B24: 13. Cuando algún amigo expresa una opinión con la que estoy muy en desacuerdo prefiero callarme a manifestar abiertamente lo que yo pienso.
... B44: 33. Hay veces que no se negarme con alguien que no me apetece pero que me llama varias veces.

Sheet RESULTADOS
B1: =CUESTIONARIO!B3 -> Isaias HURTADO SANTA CRUZ | C1: =CUESTIONARIO!C3 -> NOMBRE
B2: =CUESTIONARIO!B4 -> Isaias HURTADO SANTA CRUZ | C2: =CUESTIONARIO!C4 -> EXAMINADOR
C4: a | D4: b | E4: c | F4: d | G4: T
B5: 1. A veces evito hacer preguntas por miedo a ser estúpido | C5: =CUESTIONARIO!C12*4 -> 4 | D5: =CUESTIONARIO!D12*3 -> 0 | E5: =CUESTIONARIO!E12*2 -> 0 | F5: =CUESTIONARIO!F12*1 -> 0 | G5: =SUM(C5:F5) -> 4
B6: 2. Me cuesta telefonear a tiendas , oficinas, etc. para preguntar algo | C6: =CUESTIONARIO!C13*4 -> 0 | D6: =CUESTIONARIO!D13*3 -> 0 | E6: =CUESTIONARIO!E13*2 -> 0 | F6: =CUESTIONARIO!F13*1 -> 0 | G6: =SUM(C6:F6) -> 0
B7: 3. Si al llegar a mi casa encuentro un defecto en algo que he comprado, voy a la tienda a devolverlo. | C7: =CUESTIONARIO!C14*1 -> 0 | D7: =CUESTIONARIO!D14*2 -> 0 | E7: =CUESTIONARIO!E14*3 -> 0 | F7: =CUESTIONARIO!F14*4 -> 0 | G7: =SUM(C7:F7) -> 0
B8: 4. Cuando en una tienda atienden antes a alguien que entro después que yo, me quedo callado. | C8: =CUESTIONARIO!C15*4 -> 0 | D8: =CUESTIONARIO!D15*3 -> 0 | E8: =CUESTIONARIO!E15*2 -> 0 | F8: =CUESTIONARIO!F15*1 -> 0 | G8: =SUM(C8:F8) -> 0
B9: 5. Si un vendedor insiste en enseñarme un producto que no deseo en absoluto , paso un mal rato para decirle que “NO” | C9: =CUESTIONARIO!C16*4 -> 0 | D9: =CUESTIONARIO!D16*3 -> 0 | E9: =CUESTIONARIO!E16*2 -> 0 | F9: =CUESTIONARIO!F16*1 -> 0 | G9: =SUM(C9:F9) -> 0
B10: 6. A veces me resulta difícil pedir que me devuelvan algo que deje prestado. | C10: =CUESTIONARIO!C17*4 -> 0 | D10: =CUESTIONARIO!D17*3 -> 0 | E10: =CUESTIONARIO!E17*2 -> 0 | F10: =CUESTIONARIO!F17*1 -> 0 | G10: =SUM(C10:F10) -> 0 | I10: I | J10: II | K10: III | L10: IV | M10: V | N10: VI | O10: TOTAL
B11: 7. Si en un restauran no me traen la comida como le había pedido, llamo al camarero y pido que me hagan de nuevo. | C11: =CUESTIONARIO!C18*1 -> 0 | D11: =CUESTIONARIO!D18*2 -> 0 | E11: =CUESTIONARIO!E18*3 -> 0 | F11: =CUESTIONARIO!F18*4 -> 0 | G11: =SUM(C11:F11) -> 0 | I11: 32 | J11: 20 | K11: 16 | L11: 24 | M11: 20 | N11: 20 | O11: 132
B12: 8. A veces no se que decir a personas atractivas al sexo opuesto. | C12: =CUESTIONARIO!C19*4 -> 0 | D12: =CUESTIONARIO!D19*3 -> 0 | E12: =CUESTIONARIO!E19*2 -> 0 | F12: =CUESTIONARIO!F19*1 -> 0 | G12: =SUM(C12:F12) -> 0 | I12: =SUM(G5+G6+G14+G15+G23+G24+G32+G33) -> 4 | J12: =SUM(G7+G8+G16+G25+G34) -> 0 | K12: =SUM(G17+G26+G35+G36) -> 0 | L12: =SUM(G9+G18+G19+G27+G28+G37) -> 0 | M12: =SUM(G10+G11+G20+G29+G30) -> 0 | N12: =SUM(G12+G13+G21+G22+G31) -> 0 | O12: =SUM(I12:N12) -> 4
B13: 9. Muchas veces cuando tengo que hacer un halago no se que decir. | C13: =CUESTIONARIO!C20*4 -> 0 | D13: =CUESTIONARIO!D20*3 -> 0 | E13: =CUESTIONARIO!E20*2 -> 0 | F13: =CUESTIONARIO!F20*1 -> 0 | G13: =SUM(C13:F13) -> 0
B14: 10. Tiendo a guardar mis opiniones a mi mismo | C14: =CUESTIONARIO!C21*4 -> 0 | D14: =CUESTIONARIO!D21*3 -> 0 | E14: =CUESTIONARIO!E21*2 -> 0 | F14: =CUESTIONARIO!F21*1 -> 0 | G14: =SUM(C14:F14) -> 0
B15: 11. A veces evito ciertas reuniones sociales por miedo a hacer o decir alguna tontería. | C15: =CUESTIONARIO!C22*4 -> 0 | D15: =CUESTIONARIO!D22*3 -> 0 | E15: =CUESTIONARIO!E22*2 -> 0 | F15: =CUESTIONARIO!F22*1 -> 0 | G15: =SUM(C15:F15) -> 0
B16: 12. Si estoy en el cine y alguien me molesta con su conversación, me da mucho apuro pedirle que se calle. | C16: =CUESTIONARIO!C23*4 -> 0 | D16: =CUESTIONARIO!D23*3 -> 0 | E16: =CUESTIONARIO!E23*2 -> 0 | F16: =CUESTIONARIO!F23*1 -> 0 | G16: =SUM(C16:F16) -> 0
B17: 13. Cuando algún amigo expresa una opinión con la que estoy muy en desacuerdo prefiero callarme a manifestar abiertamente lo que yo pienso. | C17: =CUESTIONARIO!C24*4 -> 0 | D17: =CUESTIONARIO!D24*3 -> 0 | E17: =CUESTIONARIO!E24*2 -> 0 | F17: =CUESTIONARIO!F24*1 -> 0 | G17: =SUM(C17:F17) -> 0
B18: 14. Cuando tengo mucha prisa y me llama una amiga por teléfono, me cuesta mucho cortarla. | C18: =CUESTIONARIO!C25*4 -> 0 | D18: =CUESTIONARIO!D25*3 -> 0 | E18: =CUESTIONARIO!E25*2 -> 0 | F18: =CUESTIONARIO!F25*1 -> 0 | G18: =SUM(C18:F18) -> 0
B19: 15. Hay determinadas cosas que me disgusta prestar, pero si me las piden, no se como negarme. | C19: =CUESTIONARIO!C26*4 -> 0 | D19: =CUESTIONARIO!D26*3 -> 0 | E19: =CUESTIONARIO!E26*2 -> 0 | F19: =CUESTIONARIO!F26*1 -> 0 | G19: =SUM(C19:F19) -> 0
B20: 16. Si salgo de una tienda y me doy cuenta de que me han dado mal vuelto , regreso allí a pedir el cambio correcto | C20: =CUESTIONARIO!C27*1 -> 0 | D20: =CUESTIONARIO!D27*2 -> 0 | E20: =CUESTIONARIO!E27*3 -> 0 | F20: =CUESTIONARIO!F27*4 -> 0 | G20: =SUM(C20:F20) -> 0
B21: 17. No me resulta fácil hacer un cumplido a alguien que me gusta. | C21: =CUESTIONARIO!C28*4 -> 0 | D21: =CUESTIONARIO!D28*3 -> 0 | E21: =CUESTIONARIO!E28*2 -> 0 | F21: =CUESTIONARIO!F28*1 -> 0 | G21: =SUM(C21:F21) -> 0
B22: 18. Si veo en una fiesta a una persona atractiva del seco opuesto, tomo la iniciativa y me acerco a entablar conversación con ella. | C22: =CUESTIONARIO!C29*1 -> 0 | D22: =CUESTIONARIO!D29*2 -> 0 | E22: =CUESTIONARIO!E29*3 -> 0 | F22: =CUESTIONARIO!F29*4 -> 0 | G22: =SUM(C22:F22) -> 0
B23: 19. Me cuesta expresar mis sentimientos a los demás | C23: =CUESTIONARIO!C30*4 -> 0 | D23: =CUESTIONARIO!D30*3 -> 0 | E23: =CUESTIONARIO!E30*2 -> 0 | F23: =CUESTIONARIO!F30*1 -> 0 | G23: =SUM(C23:F23) -> 0
B24: 20. Si tuviera que buscar trabajo, preferiría escribir cartas de presentación a tener que pasar por entrevistas personales. | C24: =CUESTIONARIO!C31*4 -> 0 | D24: =CUESTIONARIO!D31*3 -> 0 | E24: =CUESTIONARIO!E31*2 -> 0 | F24: =CUESTIONARIO!F31*1 -> 0 | G24: =SUM(C24:F24) -> 0
B25: 21, Soy incapaz de regatear o pedir descuento al comprar algo. | C25: =CUESTIONARIO!C32*4 -> 0 | D25: =CUESTIONARIO!D32*3 -> 0 | E25: =CUESTIONARIO!E32*2 -> 0 | F25: =CUESTIONARIO!F32*1 -> 0 | G25: =SUM(C25:F25) -> 0
B26: 22. Cuando un familiar cercano me molesta , prefiero ocultar mis sentimientos antes que expresar mi enfado. | C26: =CUESTIONARIO!C33*4 -> 0 | D26: =CUESTIONARIO!D33*3 -> 0 | E26: =CUESTIONARIO!E33*2 -> 0 | F26: =CUESTIONARIO!F33*1 -> 0 | G26: =SUM(C26:F26) -> 0
B27: 23. Nunca se como “cortar “ a un amigo que habla mucho | C27: =CUESTIONARIO!C34*4 -> 0 | D27: =CUESTIONARIO!D34*3 -> 0 | E27: =CUESTIONARIO!E34*2 -> 0 | F27: =CUESTIONARIO!F34*1 -> 0 | G27: =SUM(C27:F27) -> 0
B28: 24. cuando decido que no me apetece volver a salir con una personas, me cuesta mucho comunicarle mi decisión | C28: =CUESTIONARIO!C35*4 -> 0 | D28: =CUESTIONARIO!D35*3 -> 0 | E28: =CUESTIONARIO!E35*2 -> 0 | F28: =CUESTIONARIO!F35*1 -> 0 | G28: =SUM(C28:F28) -> 0
B29: 25. Si un amigo al que he prestado cierta cantidad de dinero parece haberlo olvidado, se lo recuerdo. | C29: =CUESTIONARIO!C36*1 -> 0 | D29: =CUESTIONARIO!D36*2 -> 0 | E29: =CUESTIONARIO!E36*3 -> 0 | F29: =CUESTIONARIO!F36*4 -> 0 | G29: =SUM(C29:F29) -> 0
B30: 26. Me suele costar mucho pedir a un amigo que me haga un favor. | C30: =CUESTIONARIO!C37*4 -> 0 | D30: =CUESTIONARIO!D37*3 -> 0 | E30: =CUESTIONARIO!E37*2 -> 0 | F30: =CUESTIONARIO!F37*1 -> 0 | G30: =SUM(C30:F30) -> 0
B31: 27. Soy incapaz de pedir a alguien una cita | C31: =CUESTIONARIO!C38*4 -> 0 | D31: =CUESTIONARIO!D38*3 -> 0 | E31: =CUESTIONARIO!E38*2 -> 0 | F31: =CUESTIONARIO!F38*1 -> 0 | G31: =SUM(C31:F31) -> 0
B32: 28. Me siento turbado o violento cuando alguien del sexo opuesto me dice que le gusta algo de mi físico | C32: =CUESTIONARIO!C39*4 -> 0 | D32: =CUESTIONARIO!D39*3 -> 0 | E32: =CUESTIONARIO!E39*2 -> 0 | F32: =CUESTIONARIO!F39*1 -> 0 | G32: =SUM(C32:F32) -> 0
B33: 29. Me cuesta expresar mi opinión cuando estoy en grupo | C33: =CUESTIONARIO!C40*4 -> 0 | D33: =CUESTIONARIO!D40*3 -> 0 | E33: =CUESTIONARIO!E40*2 -> 0 | F33: =CUESTIONARIO!F40*1 -> 0 | G33: =SUM(C33:F33) -> 0
B34: 30. Cuando alguien se me” cuela” en una fila hago como si no me diera cuenta. | C34: =CUESTIONARIO!C41*4 -> 0 | D34: =CUESTIONARIO!D41*3 -> 0 | E34: =CUESTIONARIO!E41*2 -> 0 | F34: =CUESTIONARIO!F41*1 -> 0 | G34: =SUM(C34:F34) -> 0
B35: 31. Me cuesta mucho expresar mi ira , cólera, o enfado hacia el otro sexo aunque tenga motivos justificados | C35: =CUESTIONARIO!C42*4 -> 0 | D35: =CUESTIONARIO!D42*3 -> 0 | E35: =CUESTIONARIO!E42*2 -> 0 | F35: =CUESTIONARIO!F42*1 -> 0 | G35: =SUM(C35:F35) -> 0
B36: 32. Muchas veces prefiero callarme o “quitarme de en medio “para evitar problemas con otras personas. | C36: =CUESTIONARIO!C43*4 -> 0 | D36: =CUESTIONARIO!D43*3 -> 0 | E36: =CUESTIONARIO!E43*2 -> 0 | F36: =CUESTIONARIO!F43*1 -> 0 | G36: =SUM(C36:F36) -> 0
B37: 33. Hay veces que no se negarme con alguien que no me apetece pero que me llama varias veces. | C37: =CUESTIONARIO!C44*4 -> 0 | D37: =CUESTIONARIO!D44*3 -> 0 | E37: =CUESTIONARIO!E44*2 -> 0 | F37: =CUESTIONARIO!F44*1 -> 0 | G37: =SUM(C37:F37) -> 0
B38: TOTAL | C38: =SUM(C5:C37) -> 4 | D38: =SUM(D5:D37) -> 0 | E38: =SUM(E5:E37) -> 0 | F38: =SUM(F5:F37) -> 0 | G38: =SUM(C38:F38) -> 4

Sheet HOMBRES
D2: =RESULTADOS!I10 -> I | E2: =RESULTADOS!J10 -> II | F2: =RESULTADOS!K10 -> III | G2: =RESULTADOS!L10 -> IV | H2: =RESULTADOS!M10 -> V | I2: =RESULTADOS!N10 -> VI | J2: =RESULTADOS!O10 -> TOTAL
C3: PT | D3: =RESULTADOS!I11 -> 32 | E3: =RESULTADOS!J11 -> 20 | F3: =RESULTADOS!K11 -> 16 | G3: =RESULTADOS!L11 -> 24 | H3: =RESULTADOS!M11 -> 20 | I3: =RESULTADOS!N11 -> 20 | J3: =RESULTADOS!O11 -> 132
C4: PO | D4: =RESULTADOS!I12 -> 4 | E4: =RESULTADOS!J12 -> 0 | F4: =RESULTADOS!K12 -> 0 | G4: =RESULTADOS!L12 -> 0 | H4: =RESULTADOS!M12 -> 0 | I4: =RESULTADOS!N12 -> 0 | J4: =RESULTADOS!O12 -> 4
B6: BAREMO HOMBRES | F6: RESULTADO DE | H6: =CUESTIONARIO!B3 -> Isaias HURTADO SANTA CRUZ
B8: Pc | C8: En | D8: Área I | E8: Área II | F8: Área III | G8: Área IV | H8: Área V | I8: Área VI | J8: TOTAL | K8: NIVEL
B9: 99 | C9: 9 | D9: 31 – 32 | E9: 19 – 20 | F9: 17 | G9: 24 | H9: 20 | I9: 20 | J9: 127 – 133 | K9: MUY ALTO
B10: 98 | C10: 9 | D10: 30 | E10: 18 | G10: 23 | H10: 19 | J10: 124 – 126
B11: 97 | C11: 9 | F11: 16 | J11: 122 – 123
B12: 96 | C12: 8 | D12: 29 | G12: 22 | I12: 19 | J12: 121 | K12: ALTO
B13: 95 | C13: 8 | E13: 17 | J13: 118 – 120
B14: 94 | C14: 8 | F14: 15 | H14: 18 | I14: 18 | J14: 117
B15: 93 | C15: 8 | D15: 28 | J15: 115 – 116
B16: 92 | C16: 8 | G16: 21 | J16: 114
B17: 91 | C17: 8 | J17: 113
B18: 90 | C18: 8 | E18: 16
B19: 89 | C19: 7 | F19: 14 | H19: 17 | J19: 112
B20: 88 | C20: 7 | D20: 27 | J20: 111
B21: 87 | C21: 7 | I21: 17
B22: 86 | C22: 7 | J22: 108 – 110
B23: 85 | C23: 7 | G23: 20
B24: 84 | C24: 7 | J24: 107
B25: 83 | C25: 7 | D25: 26
B26: 82 | C26: 7 | F26: 13 | H26: 16
B27: 81 | C27: 7 | J27: 106
B28: 80 | C28: 7 | E28: 15 | J28: 105
B29: 79 | C29: 7 | J29: 104
B30: 78 | C30: 7 | G30: 19
B31: 77 | C31: 7 | J31: 103
B32: 76 | C32: 7 | D32: 25 | I32: 16
B33: 75 | C33: 7 | J33: 102
B34: 74 | C34: 6 | J34: 101 | K34: NORMAL ALTO
B35: 73 | C35: 6 | J35: 100
B36: 72 | C36: 6 | J36: 99
B37: 71 | C37: 6 | H37: 15
B38: 70 | C38: 6 | F38: 12
B39: 69 | C39: 6 | G39: 18
B40: 68 | C40: 6 | D40: 24 | J40: 98
B41: 66 | C41: 6 | E41: 14
B42: 65 | C42: 6 | I42: 15
B43: 64 | C43: 6 | J43: 96 – 97
...

Sheet MUJERES
D2: =RESULTADOS!I10 -> I | E2: =RESULTADOS!J10 -> II | F2: =RESULTADOS!K10 -> III | G2: =RESULTADOS!L10 -> IV | H2: =RESULTADOS!M10 -> V | I2: =RESULTADOS!N10 -> VI | J2: =RESULTADOS!O10 -> TOTAL
C3: PT | D3: =RESULTADOS!I11 -> 32 | E3: =RESULTADOS!J11 -> 20 | F3: =RESULTADOS!K11 -> 16 | G3: =RESULTADOS!L11 -> 24 | H3: =RESULTADOS!M11 -> 20 | I3: =RESULTADOS!N11 -> 20 | J3: =RESULTADOS!O11 -> 132
C4: PO | D4: =RESULTADOS!I12 -> 4 | E4: =RESULTADOS!J12 -> 0 | F4: =RESULTADOS!K12 -> 0 | G4: =RESULTADOS!L12 -> 0 | H4: =RESULTADOS!M12 -> 0 | I4: =RESULTADOS!N12 -> 0 | J4: =RESULTADOS!O12 -> 4
B6: BAREMO MUJERES | F6: RESULTADO DE | H6: =CUESTIONARIO!B3 -> Isaias HURTADO SANTA CRUZ
B8: Pc | C8: En | D8: Área I | E8: Área II | F8: Área III | G8: Área IV | H8: Área V | I8: Área VI | J8: TOTAL | K8: NIVEL
B9: 99 | C9: 9 | D9: 31 – 32 | E9: 20 | F9: 16 | G9: 25 – 29 | H9: 20 | I9: 18 – 20 | J9: 128 – 137 | K9: MUY ALTO
B10: 98 | C10: 9 | E10: 19 | G10: 24 | H10: 19 | J10: 125 – 127
B11: 97 | C11: 9 | D11: 30 | J11: 122 – 124
B12: 96 | C12: 8 | F12: 15 | G12: 23 | J12: 121 | K12: ALTO
B13: 95 | C13: 8 | D13: 29 | E13: 18 | J13: 120
B14: 94 | C14: 8 | G14: 22 | H14: 18 | I14: 17 | J14: 118 – 119
B15: 93 | C15: 8 | J15: 115 – 117
B16: 91 | C16: 8 | D16: 28 | G16: 21 | J16: 114
B17: 90 | C17: 8 | E17: 17 | F17: 14
B18: 89 | C18: 7 | H18: 17 | J18: 112 – 113
B19: 88 | C19: 7 | J19: 111
B20: 87 | C20: 7 | J20: 109 – 110
B21: 86 | C21: 7 | D21: 27 | G21: 20
B22: 85 | C22: 7 | I22: 16 | J22: 108
B23: 83 | C23: 7 | H23: 16 | J23: 107
B24: 82 | C24: 7 | J24: 106
B25: 81 | C25: 7 | E25: 16
B26: 80 | C26: 7 | F26: 13 | J26: 105
B27: 78 | C27: 7 | D27: 26 | G27: 19
B28: 77 | C28: 7 | J28: 104
B29: 74 | C29: 6 | H29: 15 | J29: 103 | K29: NORMAL ALTO
B30: 73 | C30: 6 | I30: 15 | J30: 101 – 102
B31: 70 | C31: 6 | G31: 18 | J31: 100
B32: 68 | C32: 6 | D32: 25
B33: 67 | C33: 6 | E33: 15 | J33: 99
B34: 66 | C34: 6 | J34: 98
B35: 65 | C35: 6 | F35: 12
B36: 64 | C36: 6 | J36: 97
B37: 61 | C37: 6 | G37: 17 | I37: 14 | J37: 96
B38: 60 | C38: 5 | H38: 14 | K38: NORMAL
B39: 59 | C39: 5 | J39: 95
B40: 58 | C40: 5 | D40: 24
B41: 57 | C41: 5 | J41: 94
B42: 55 | C42: 5 | J42: 93
B43: 54 | C43: 5 | E43: 14 | F43: 11 | J43: 92
...
